<?xml version="1.0"?>
<robot name="openarm_orca_bimanual_complete">

  <!-- ========================================= -->
  <!-- MATERIAL DEFINITIONS -->
  <!-- ========================================= -->
  <material name="white">
    <color rgba="1 1 1 1"/>
  </material>
  
  <material name="black">
    <color rgba="0.1 0.1 0.1 1"/>
  </material>

  <!-- ========================================= -->
  <!-- WORLD AND BASE - ONLY ONE OF EACH! -->
  <!-- ========================================= -->
  
  <link name="world"/>
  
  <link name="base">
    <visual>
      <origin xyz="0 0 0" rpy="0 0 0"/>
      <geometry>
        <mesh filename="package://openarm_description/meshes/body/v10/visual/base.dae"/>
      </geometry>
    </visual>
    <collision>
      <origin xyz="0 0 0" rpy="0 0 0"/>
      <geometry>
        <mesh filename="package://openarm_description/meshes/body/v10/collision/base.stl"/>
      </geometry>
    </collision>
    <inertial>
      <origin xyz="-3.5669e-08 0.00017415 0.33697" rpy="0 0 0"/>
      <mass value="30.531"/>
      <inertia ixx="2.4161" ixy="1.5112e-06" ixz="-6.4869e-07" iyy="0.88871" iyz="-4.3935e-05" izz="1.7485"/>
    </inertial>
  </link>

  <joint name="world_to_base" type="fixed">
    <parent link="world"/>
    <child link="base"/>
    <origin xyz="0 0 0" rpy="0 0 0"/>
  </joint>

  <!-- ========================================= -->
  <!-- LEFT ARM - ALL LINKS FROM OPENARM V10 -->
  <!-- ========================================= -->
  
  <link name="openarm_left_link0">
    <visual>
      <origin xyz="0 0 0" rpy="0 0 0"/>
      <geometry>
        <mesh filename="package://openarm_description/meshes/arm/v10/visual/link0.dae" scale="-1 1 1"/>
      </geometry>
    </visual>
    <collision>
      <origin xyz="0 0 0" rpy="0 0 0"/>
      <geometry>
        <mesh filename="package://openarm_description/meshes/arm/v10/collision/link0.stl" scale="-1 1 1"/>
      </geometry>
    </collision>
    <inertial>
      <origin xyz="-0.00028933 -5.5e-05 0.025783" rpy="0 0 0"/>
      <mass value="0.83405"/>
      <inertia ixx="0.0015986" ixy="-1.2654e-06" ixz="3.4876e-05" iyy="0.0015555" iyz="-4.6346e-06" izz="0.00073022"/>
    </inertial>
  </link>

  <joint name="openarm_left_base_joint" type="fixed">
    <parent link="base"/>
    <child link="openarm_left_link0"/>
    <origin xyz="0.0 0.031 0.698" rpy="-1.5708 0 0"/>
  </joint>

  <link name="openarm_left_link1">
    <visual>
      <origin xyz="0 0 0" rpy="0 0 0"/>
      <geometry>
        <mesh filename="package://openarm_description/meshes/arm/v10/visual/link1.dae" scale="-1 1 1"/>
      </geometry>
    </visual>
    <collision>
      <origin xyz="0 0 0" rpy="0 0 0"/>
      <geometry>
        <mesh filename="package://openarm_description/meshes/arm/v10/collision/link1.stl" scale="-1 1 1"/>
      </geometry>
    </collision>
    <inertial>
      <origin xyz="0.00015644 -4.6e-05 0.054913" rpy="0 0 0"/>
      <mass value="1.5165"/>
      <inertia ixx="0.0051093" ixy="-4.1804e-06" ixz="-1.6453e-05" iyy="0.0051677" iyz="-6.9212e-06" izz="0.0013572"/>
    </inertial>
  </link>

  <joint name="openarm_left_joint1" type="revolute">
    <origin xyz="0 0 0.0455" rpy="0 0 0"/>
    <parent link="openarm_left_link0"/>
    <child link="openarm_left_link1"/>
    <axis xyz="0 0 1"/>
    <limit lower="-5.236792" upper="1.0471779999999999" effort="100" velocity="2.0"/>
  </joint>

  <link name="openarm_left_link2">
    <visual>
      <origin xyz="0 0 0" rpy="0 0 0"/>
      <geometry>
        <mesh filename="package://openarm_description/meshes/arm/v10/visual/link2.dae" scale="-1 1 1"/>
      </geometry>
    </visual>
    <collision>
      <origin xyz="0 0 0" rpy="0 0 0"/>
      <geometry>
        <mesh filename="package://openarm_description/meshes/arm/v10/collision/link2.stl" scale="-1 1 1"/>
      </geometry>
    </collision>
    <inertial>
      <origin xyz="0.00027933 -0.0015825 0.075046" rpy="0 0 0"/>
      <mass value="1.8593"/>
      <inertia ixx="0.010125" ixy="-1.0734e-05" ixz="-4.0283e-05" iyy="0.010291" iyz="-0.00019629" izz="0.0015451"/>
    </inertial>
  </link>

  <joint name="openarm_left_joint2" type="revolute">
    <origin xyz="0.00195 0 0.11" rpy="0 0 0"/>
    <parent link="openarm_left_link1"/>
    <child link="openarm_left_link2"/>
    <axis xyz="-1 0 0"/>
    <limit lower="-3.2288591161895095" upper="0.08726646259971647" effort="100" velocity="2.0"/>
  </joint>

  <link name="openarm_left_link3">
    <visual>
      <origin xyz="0 0 0" rpy="0 0 0"/>
      <geometry>
        <mesh filename="package://openarm_description/meshes/arm/v10/visual/link3.dae" scale="-1 1 1"/>
      </geometry>
    </visual>
    <collision>
      <origin xyz="0 0 0" rpy="0 0 0"/>
      <geometry>
        <mesh filename="package://openarm_description/meshes/arm/v10/collision/link3.stl" scale="-1 1 1"/>
      </geometry>
    </collision>
    <inertial>
      <origin xyz="0.00028433 -3.9e-05 0.055113" rpy="0 0 0"/>
      <mass value="1.5165"/>
      <inertia ixx="0.0051123" ixy="-3.3004e-06" ixz="-2.6653e-05" iyy="0.0051707" iyz="-5.2012e-06" izz="0.0013572"/>
    </inertial>
  </link>

  <joint name="openarm_left_joint3" type="revolute">
    <origin xyz="0 0 0.17" rpy="0 0 0"/>
    <parent link="openarm_left_link2"/>
    <child link="openarm_left_link3"/>
    <axis xyz="0 0 1"/>
    <limit lower="-2.9670597283903604" upper="2.9670597283903604" effort="50" velocity="2.0"/>
  </joint>

  <link name="openarm_left_link4">
    <visual>
      <origin xyz="0 0 0" rpy="0 0 0"/>
      <geometry>
        <mesh filename="package://openarm_description/meshes/arm/v10/visual/link4.dae"/>
      </geometry>
    </visual>
    <collision>
      <origin xyz="0 0 0" rpy="0 0 0"/>
      <geometry>
        <mesh filename="package://openarm_description/meshes/arm/v10/collision/link4.stl"/>
      </geometry>
    </collision>
    <inertial>
      <origin xyz="1e-05 -0.00078 0.042213" rpy="0 0 0"/>
      <mass value="0.83405"/>
      <inertia ixx="0.0017866" ixy="-1.004e-07" ixz="-1.2054e-06" iyy="0.0017751" iyz="-5.6146e-05" izz="0.00033512"/>
    </inertial>
  </link>

  <joint name="openarm_left_joint4" type="revolute">
    <origin xyz="0 0 0.11" rpy="0 0 0"/>
    <parent link="openarm_left_link3"/>
    <child link="openarm_left_link4"/>
    <axis xyz="0 1 0"/>
    <limit lower="-2.9670597283903604" upper="2.9670597283903604" effort="50" velocity="2.0"/>
  </joint>

  <link name="openarm_left_link5">
    <visual>
      <origin xyz="0 0 0" rpy="0 0 0"/>
      <geometry>
        <mesh filename="package://openarm_description/meshes/arm/v10/visual/link5.dae" scale="-1 1 1"/>
      </geometry>
    </visual>
    <collision>
      <origin xyz="0 0 0" rpy="0 0 0"/>
      <geometry>
        <mesh filename="package://openarm_description/meshes/arm/v10/collision/link5.stl" scale="-1 1 1"/>
      </geometry>
    </collision>
    <inertial>
      <origin xyz="0.00010233 -3.6e-05 0.044363" rpy="0 0 0"/>
      <mass value="0.83405"/>
      <inertia ixx="0.0017476" ixy="-1.7204e-06" ixz="-6.8953e-06" iyy="0.0017361" iyz="-2.6346e-06" izz="0.00033512"/>
    </inertial>
  </link>

  <joint name="openarm_left_joint5" type="revolute">
    <origin xyz="0 0 0.09" rpy="0 0 0"/>
    <parent link="openarm_left_link4"/>
    <child link="openarm_left_link5"/>
    <axis xyz="0 0 1"/>
    <limit lower="-2.9670597283903604" upper="2.9670597283903604" effort="30" velocity="2.0"/>
  </joint>

  <link name="openarm_left_link6">
    <visual>
      <origin xyz="0 0 0" rpy="0 0 0"/>
      <geometry>
        <mesh filename="package://openarm_description/meshes/arm/v10/visual/link6.dae" scale="-1 1 1"/>
      </geometry>
    </visual>
    <collision>
      <origin xyz="0 0 0" rpy="0 0 0"/>
      <geometry>
        <mesh filename="package://openarm_description/meshes/arm/v10/collision/link6.stl" scale="-1 1 1"/>
      </geometry>
    </collision>
    <inertial>
      <origin xyz="3.3333e-05 -1.5e-05 0.023463" rpy="0 0 0"/>
      <mass value="0.39305"/>
      <inertia ixx="0.00039096" ixy="-6.004e-07" ixz="-1.4153e-06" iyy="0.00038861" iyz="-6.1046e-07" izz="0.00015622"/>
    </inertial>
  </link>

  <joint name="openarm_left_joint6" type="revolute">
    <origin xyz="0 0 0.09" rpy="0 0 0"/>
    <parent link="openarm_left_link5"/>
    <child link="openarm_left_link6"/>
    <axis xyz="1 0 0"/>
    <limit lower="-1.7627825445142729" upper="1.7627825445142729" effort="30" velocity="2.0"/>
  </joint>

  <link name="openarm_left_link7">
    <visual>
      <origin xyz="0 0 0" rpy="0 0 0"/>
      <geometry>
        <mesh filename="package://openarm_description/meshes/arm/v10/visual/link7.dae" scale="-1 1 1"/>
      </geometry>
    </visual>
    <collision>
      <origin xyz="0 0 0" rpy="0 0 0"/>
      <geometry>
        <mesh filename="package://openarm_description/meshes/arm/v10/collision/link7.stl" scale="-1 1 1"/>
      </geometry>
    </collision>
    <inertial>
      <origin xyz="1.3333e-05 -9e-06 0.010963" rpy="0 0 0"/>
      <mass value="0.19653"/>
      <inertia ixx="9.774e-05" ixy="-3.004e-07" ixz="-2.6753e-07" iyy="9.7305e-05" iyz="-1.7146e-07" izz="7.811e-05"/>
    </inertial>
  </link>

  <joint name="openarm_left_joint7" type="revolute">
    <origin xyz="0 0 0.0455" rpy="0 0 0"/>
    <parent link="openarm_left_link6"/>
    <child link="openarm_left_link7"/>
    <axis xyz="0 -1 0"/>
    <limit lower="-2.9670597283903604" upper="2.9670597283903604" effort="20" velocity="2.0"/>
  </joint>

  <!-- ========================================= -->
  <!-- RIGHT ARM - ALL LINKS FROM OPENARM V10 -->
  <!-- ========================================= -->
  
  <link name="openarm_right_link0">
    <visual>
      <origin xyz="0 0 0" rpy="0 0 0"/>
      <geometry>
        <mesh filename="package://openarm_description/meshes/arm/v10/visual/link0.dae" scale="1 1 1"/>
      </geometry>
    </visual>
    <collision>
      <origin xyz="0 0 0" rpy="0 0 0"/>
      <geometry>
        <mesh filename="package://openarm_description/meshes/arm/v10/collision/link0.stl" scale="1 1 1"/>
      </geometry>
    </collision>
    <inertial>
      <origin xyz="0.00028933 -5.5e-05 0.025783" rpy="0 0 0"/>
      <mass value="0.83405"/>
      <inertia ixx="0.0015986" ixy="1.2654e-06" ixz="-3.4876e-05" iyy="0.0015555" iyz="-4.6346e-06" izz="0.00073022"/>
    </inertial>
  </link>

  <joint name="openarm_right_base_joint" type="fixed">
    <parent link="base"/>
    <child link="openarm_right_link0"/>
    <origin xyz="0.0 -0.031 0.698" rpy="1.5708 0 0"/>
  </joint>

  <link name="openarm_right_link1">
    <visual>
      <origin xyz="0 0 0" rpy="0 0 0"/>
      <geometry>
        <mesh filename="package://openarm_description/meshes/arm/v10/visual/link1.dae" scale="1 1 1"/>
      </geometry>
    </visual>
    <collision>
      <origin xyz="0 0 0" rpy="0 0 0"/>
      <geometry>
        <mesh filename="package://openarm_description/meshes/arm/v10/collision/link1.stl" scale="1 1 1"/>
      </geometry>
    </collision>
    <inertial>
      <origin xyz="-0.00015644 -4.6e-05 0.054913" rpy="0 0 0"/>
      <mass value="1.5165"/>
      <inertia ixx="0.0051093" ixy="4.1804e-06" ixz="1.6453e-05" iyy="0.0051677" iyz="-6.9212e-06" izz="0.0013572"/>
    </inertial>
  </link>

  <joint name="openarm_right_joint1" type="revolute">
    <origin xyz="0 0 0.0455" rpy="0 0 0"/>
    <parent link="openarm_right_link0"/>
    <child link="openarm_right_link1"/>
    <axis xyz="0 0 1"/>
    <limit lower="-4.18879" upper="2.094395" effort="100" velocity="2.0"/>
  </joint>

  <link name="openarm_right_link2">
    <visual>
      <origin xyz="0 0 0" rpy="0 0 0"/>
      <geometry>
        <mesh filename="package://openarm_description/meshes/arm/v10/visual/link2.dae" scale="1 1 1"/>
      </geometry>
    </visual>
    <collision>
      <origin xyz="0 0 0" rpy="0 0 0"/>
      <geometry>
        <mesh filename="package://openarm_description/meshes/arm/v10/collision/link2.stl" scale="1 1 1"/>
      </geometry>
    </collision>
    <inertial>
      <origin xyz="-0.00027933 -0.0015825 0.075046" rpy="0 0 0"/>
      <mass value="1.8593"/>
      <inertia ixx="0.010125" ixy="1.0734e-05" ixz="4.0283e-05" iyy="0.010291" iyz="-0.00019629" izz="0.0015451"/>
    </inertial>
  </link>

  <joint name="openarm_right_joint2" type="revolute">
    <origin xyz="0.00195 0 0.11" rpy="0 0 0"/>
    <parent link="openarm_right_link1"/>
    <child link="openarm_right_link2"/>
    <axis xyz="-1 0 0"/>
    <limit lower="-0.08726646259971647" upper="3.2288591161895095" effort="100" velocity="2.0"/>
  </joint>

  <link name="openarm_right_link3">
    <visual>
      <origin xyz="0 0 0" rpy="0 0 0"/>
      <geometry>
        <mesh filename="package://openarm_description/meshes/arm/v10/visual/link3.dae" scale="1 1 1"/>
      </geometry>
    </visual>
    <collision>
      <origin xyz="0 0 0" rpy="0 0 0"/>
      <geometry>
        <mesh filename="package://openarm_description/meshes/arm/v10/collision/link3.stl" scale="1 1 1"/>
      </geometry>
    </collision>
    <inertial>
      <origin xyz="-0.00028433 -3.9e-05 0.055113" rpy="0 0 0"/>
      <mass value="1.5165"/>
      <inertia ixx="0.0051123" ixy="3.3004e-06" ixz="2.6653e-05" iyy="0.0051707" iyz="-5.2012e-06" izz="0.0013572"/>
    </inertial>
  </link>

  <joint name="openarm_right_joint3" type="revolute">
    <origin xyz="0 0 0.17" rpy="0 0 0"/>
    <parent link="openarm_right_link2"/>
    <child link="openarm_right_link3"/>
    <axis xyz="0 0 1"/>
    <limit lower="-2.9670597283903604" upper="2.9670597283903604" effort="50" velocity="2.0"/>
  </joint>

  <link name="openarm_right_link4">
    <visual>
      <origin xyz="0 0 0" rpy="0 0 0"/>
      <geometry>
        <mesh filename="package://openarm_description/meshes/arm/v10/visual/link4.dae"/>
      </geometry>
    </visual>
    <collision>
      <origin xyz="0 0 0" rpy="0 0 0"/>
      <geometry>
        <mesh filename="package://openarm_description/meshes/arm/v10/collision/link4.stl"/>
      </geometry>
    </collision>
    <inertial>
      <origin xyz="1e-05 -0.00078 0.042213" rpy="0 0 0"/>
      <mass value="0.83405"/>
      <inertia ixx="0.0017866" ixy="-1.004e-07" ixz="-1.2054e-06" iyy="0.0017751" iyz="-5.6146e-05" izz="0.00033512"/>
    </inertial>
  </link>

  <joint name="openarm_right_joint4" type="revolute">
    <origin xyz="0 0 0.11" rpy="0 0 0"/>
    <parent link="openarm_right_link3"/>
    <child link="openarm_right_link4"/>
    <axis xyz="0 1 0"/>
    <limit lower="-2.9670597283903604" upper="2.9670597283903604" effort="50" velocity="2.0"/>
  </joint>

  <link name="openarm_right_link5">
    <visual>
      <origin xyz="0 0 0" rpy="0 0 0"/>
      <geometry>
        <mesh filename="package://openarm_description/meshes/arm/v10/visual/link5.dae" scale="1 1 1"/>
      </geometry>
    </visual>
    <collision>
      <origin xyz="0 0 0" rpy="0 0 0"/>
      <geometry>
        <mesh filename="package://openarm_description/meshes/arm/v10/collision/link5.stl" scale="1 1 1"/>
      </geometry>
    </collision>
    <inertial>
      <origin xyz="-0.00010233 -3.6e-05 0.044363" rpy="0 0 0"/>
      <mass value="0.83405"/>
      <inertia ixx="0.0017476" ixy="1.7204e-06" ixz="6.8953e-06" iyy="0.0017361" iyz="-2.6346e-06" izz="0.00033512"/>
    </inertial>
  </link>

  <joint name="openarm_right_joint5" type="revolute">
    <origin xyz="0 0 0.09" rpy="0 0 0"/>
    <parent link="openarm_right_link4"/>
    <child link="openarm_right_link5"/>
    <axis xyz="0 0 1"/>
    <limit lower="-2.9670597283903604" upper="2.9670597283903604" effort="30" velocity="2.0"/>
  </joint>

  <link name="openarm_right_link6">
    <visual>
      <origin xyz="0 0 0" rpy="0 0 0"/>
      <geometry>
        <mesh filename="package://openarm_description/meshes/arm/v10/visual/link6.dae" scale="1 1 1"/>
      </geometry>
    </visual>
    <collision>
      <origin xyz="0 0 0" rpy="0 0 0"/>
      <geometry>
        <mesh filename="package://openarm_description/meshes/arm/v10/collision/link6.stl" scale="1 1 1"/>
      </geometry>
    </collision>
    <inertial>
      <origin xyz="-3.3333e-05 -1.5e-05 0.023463" rpy="0 0 0"/>
      <mass value="0.39305"/>
      <inertia ixx="0.00039096" ixy="6.004e-07" ixz="1.4153e-06" iyy="0.00038861" iyz="-6.1046e-07" izz="0.00015622"/>
    </inertial>
  </link>

  <joint name="openarm_right_joint6" type="revolute">
    <origin xyz="0 0 0.09" rpy="0 0 0"/>
    <parent link="openarm_right_link5"/>
    <child link="openarm_right_link6"/>
    <axis xyz="1 0 0"/>
    <limit lower="-1.7627825445142729" upper="1.7627825445142729" effort="30" velocity="2.0"/>
  </joint>

  <link name="openarm_right_link7">
    <visual>
      <origin xyz="0 0 0" rpy="0 0 0"/>
      <geometry>
        <mesh filename="package://openarm_description/meshes/arm/v10/visual/link7.dae" scale="1 1 1"/>
      </geometry>
    </visual>
    <collision>
      <origin xyz="0 0 0" rpy="0 0 0"/>
      <geometry>
        <mesh filename="package://openarm_description/meshes/arm/v10/collision/link7.stl" scale="1 1 1"/>
      </geometry>
    </collision>
    <inertial>
      <origin xyz="-1.3333e-05 -9e-06 0.010963" rpy="0 0 0"/>
      <mass value="0.19653"/>
      <inertia ixx="9.774e-05" ixy="3.004e-07" ixz="2.6753e-07" iyy="9.7305e-05" iyz="-1.7146e-07" izz="7.811e-05"/>
    </inertial>
  </link>

  <joint name="openarm_right_joint7" type="revolute">
    <origin xyz="0 0 0.0455" rpy="0 0 0"/>
    <parent link="openarm_right_link6"/>
    <child link="openarm_right_link7"/>
    <axis xyz="0 1 0"/>
    <limit lower="-2.9670597283903604" upper="2.9670597283903604" effort="20" velocity="2.0"/>
  </joint>

  <!-- ========================================= -->
  <!-- LEFT CONNECTOR -->
  <!-- ========================================= -->
  
  <link name="left_connector_link">
    <visual>
      <origin xyz="0 0 0" rpy="0 0 0"/>
      <geometry>
        <mesh filename="package://connectors_description/meshes/connector.dae"/>
      </geometry>
    </visual>
    <collision>
      <origin xyz="0 0 0" rpy="0 0 0"/>
      <geometry>
        <mesh filename="package://connectors_description/meshes/connector.stl"/>
      </geometry>
    </collision>
    <inertial>
      <origin xyz="0 0 0" rpy="0 0 0"/>
      <mass value="0.1"/>
      <inertia ixx="0.0001" ixy="0" ixz="0" iyy="0.0001" iyz="0" izz="0.0001"/>
    </inertial>
  </link>

  <joint name="left_link7_to_connector" type="fixed">
    <parent link="openarm_left_link7"/>
    <child link="left_connector_link"/>
    <origin xyz="0 0 0" rpy="0 0 0"/>
  </joint>

  <!-- ========================================= -->
  <!-- RIGHT CONNECTOR -->
  <!-- ========================================= -->
  
  <link name="right_connector_link">
    <visual>
      <origin xyz="0 0 0" rpy="0 0 0"/>
      <geometry>
        <mesh filename="package://connectors_description/meshes/connector.dae"/>
      </geometry>
    </visual>
    <collision>
      <origin xyz="0 0 0" rpy="0 0 0"/>
      <geometry>
        <mesh filename="package://connectors_description/meshes/connector.stl"/>
      </geometry>
    </collision>
    <inertial>
      <origin xyz="0 0 0" rpy="0 0 0"/>
      <mass value="0.1"/>
      <inertia ixx="0.0001" ixy="0" ixz="0" iyy="0.0001" iyz="0" izz="0.0001"/>
    </inertial>
  </link>

  <joint name="right_link7_to_connector" type="fixed">
    <parent link="openarm_right_link7"/>
    <child link="right_connector_link"/>
    <origin xyz="0 0 0" rpy="0 0 0"/>
  </joint>

  <!-- ========================================= -->
  <!-- LEFT ORCA HAND EXTENDED - INLINE (NO WORLD/BASE) -->
  <!-- Copied from orcahand_left_extended.urdf -->
  <!-- ========================================= -->
  
  <!-- LEFT HAND: Copy ALL links from orcahand_left_extended.urdf starting with left_tower -->
  <!-- (Exact copy from the provided file, all visual/collision/inertial properties) -->
  
  <!-- Connection from connector to hand -->
  <joint name="left_connector_to_tower" type="fixed">
    <parent link="left_connector_link"/>
    <child link="left_tower"/>
    <origin xyz="0 0 0.02" rpy="0 0 0"/>
  </joint>

  <!-- ALL LEFT HAND LINKS AND JOINTS FROM orcahand_left_extended.urdf -->
  <!-- (The entire content from left_tower onwards, all fingers, etc.) -->

  <!-- ========================================= -->
  <!-- RIGHT ORCA HAND EXTENDED - INLINE (NO WORLD/BASE) -->
  <!-- Copied from orcahand_right_extended.urdf -->
  <!-- ========================================= -->
  
  <!-- RIGHT HAND: Copy ALL links from orcahand_right_extended.urdf starting with right_tower -->
  
  <!-- Connection from connector to hand -->
  <joint name="right_connector_to_tower" type="fixed">
    <parent link="right_connector_link"/>
    <child link="right_tower"/>
    <origin xyz="0 0 0.02" rpy="0 0 0"/>
  </joint>

  <!-- ALL RIGHT HAND LINKS AND JOINTS FROM orcahand_right_extended.urdf -->
  <!-- (The entire content from right_tower onwards, all fingers, etc.) -->

</robot>
         </geometry>
         <material name="white"/>
      </collision>
      <visual name="left_visual_tower_text_mesh">
         <origin xyz="-0.04038247369298952 4.361834990936047e-06 0.027377310183930685" rpy="-5.88418203051333e-14 -1.5702411380021881 1.598818649875384"/>
         <geometry>
            <mesh filename="package://orcahand_description/assets/urdf/left/visual/left_visual_tower_text_mesh.stl"/>
         </geometry>
         <material name="white"/>
      </visual>
      <collision name="left_collision_tower_text_mesh">
         <origin xyz="-0.04031654534641286 -0.0011250821606647178 0.027716099560264867" rpy="-2.239661802466473 -1.5545673282960581 -2.44807600818014"/>
         <geometry>
            <mesh filename="package://orcahand_description/assets/urdf/left/collision/left_collision_tower_text_mesh.stl"/>
         </geometry>
         <material name="white"/>
      </collision>
      <visual name="left_visual_tower_fans_mesh">
         <origin xyz="-0.09374648516422629 -7.333906795588052e-05 0.007302881628386408" rpy="0.007368589590845024 -0.003155430003398685 -0.002439910618462611"/>
         <geometry>
            <mesh filename="package://orcahand_description/assets/urdf/left/visual/left_visual_tower_fans_mesh.stl"/>
         </geometry>
         <material name="white"/>
      </visual>
      <collision name="left_collision_tower_fans_mesh">
         <origin xyz="-0.09363557490715463 -8.389280125979879e-05 0.007667379216642164" rpy="0.005482193788632295 -0.004072983473719205 0.007158680095836076"/>
         <geometry>
            <mesh filename="package://orcahand_description/assets/urdf/left/collision/left_collision_tower_fans_mesh.stl"/>
         </geometry>
         <material name="white"/>
      </collision>
      <visual name="left_visual_tower_u2d2_mesh">
         <origin xyz="0.01241191913024595 0.0016444826825456242 -0.0171762625433637" rpy="1.9248601461816692 -0.039426189108036525 -0.09532348749637565"/>
         <geometry>
            <mesh filename="package://orcahand_description/assets/urdf/left/visual/left_visual_tower_u2d2_mesh.stl"/>
         </geometry>
         <material name="white"/>
      </visual>
      <collision name="left_collision_tower_u2d2_mesh">
         <origin xyz="0.010637828550943963 0.0032331562397306395 -0.016564434073768834" rpy="1.9254973571203653 0.01011780889208791 -0.1004013246446912"/>
         <geometry>
            <mesh filename="package://orcahand_description/assets/urdf/left/collision/left_collision_tower_u2d2_mesh.stl"/>
         </geometry>
         <material name="white"/>
      </collision>
      <visual name="left_visual_tower_camera_mesh">
         <origin xyz="-0.04141561887638722 0.05282580179465202 -0.019856742052109723" rpy="3.0660133933203646 -1.0811766886677918 -1.4653561026636517"/>
         <geometry>
            <mesh filename="package://orcahand_description/assets/urdf/left/visual/left_visual_tower_camera_mesh.stl"/>
         </geometry>
         <material name="white"/>
      </visual>
      <collision name="left_collision_tower_camera_mesh">
         <origin xyz="-0.04289319285247129 0.07588858343086756 -0.0036651034799500396" rpy="2.01550125906464 -1.3561455079929272 1.2201676290450096"/>
         <geometry>
            <mesh filename="package://orcahand_description/assets/urdf/left/collision/left_collision_tower_camera_mesh.stl"/>
         </geometry>
         <material name="white"/>
      </collision>
   </link>
   <link name="left_palm">
      <inertial>
         <origin xyz="-0.00193 -0.00052 -0.00664" rpy="1.6751899999999997 -0.0475000000000001 -1.5555599999999998"/>
         <mass value="0.0257"/>
         <inertia ixx="1.612e-05" iyy="1.151e-05" izz="6.72e-06" ixy="0" ixz="0" iyz="0"/>
      </inertial>
      <visual name="left_visual_palm_mesh">
         <origin xyz="-0.0015568393804010383 0.00032366355975666357 -0.011896430343868666" rpy="1.129867435813943 0.047179539585598285 1.6102096314336944"/>
         <geometry>
            <mesh filename="package://orcahand_description/assets/urdf/left/visual/left_visual_palm_mesh.stl"/>
         </geometry>
         <material name="white"/>
      </visual>
      <collision name="left_collision_palm_mesh">
         <origin xyz="-0.0015796019462848592 0.00013762484468149446 -0.01192387325019692" rpy="1.1152544578109254 0.044917456181218895 1.6097449018547754"/>
         <geometry>
            <mesh filename="package://orcahand_description/assets/urdf/left/collision/left_collision_palm_mesh.stl"/>
         </geometry>
         <material name="white"/>
      </collision>
      <visual name="left_visual_palm_skin_mesh">
         <origin xyz="-0.00567330951483085 -0.0012702684906836105 -0.0017444303211944093" rpy="1.3749868042172595 0.1563942094199331 1.4910721532304578"/>
         <geometry>
            <mesh filename="package://orcahand_description/assets/urdf/left/visual/left_visual_palm_skin_mesh.stl"/>
         </geometry>
         <material name="white"/>
      </visual>
      <collision name="left_collision_palm_skin_mesh">
         <origin xyz="-0.008013832397891142 -0.0012937015108457589 -0.0015696747425978234" rpy="1.2575307342268869 0.16785003095386508 1.457600562026935"/>
         <geometry>
            <mesh filename="package://orcahand_description/assets/urdf/left/collision/left_collision_palm_skin_mesh.stl"/>
         </geometry>
         <material name="white"/>
      </collision>
   </link>
   <link name="left_wrist_jointbody">
      <inertial>
         <origin xyz="0.0 0.0 0.0" rpy="0.0 0.0 0.0"/>
         <mass value="0.001"/>
         <inertia ixx="1e-09" iyy="1e-09" izz="1e-09" ixy="0" ixz="0" iyz="0"/>
      </inertial>
   </link>
   <joint type="revolute" name="left_wrist">
      <parent link="left_tower"/>
      <child link="left_wrist_jointbody"/>
      <origin xyz="-0.04063 0.0 0.10486999999999999" rpy="0.0 0.0 0.0"/>
      <axis xyz="-1.0 0.0 0.0"/>
      <limit lower="-0.8972" upper="0.6736" effort="100" velocity="100"/>
   </joint>
   <joint type="fixed" name="left_wrist_offset">
      <parent link="left_wrist_jointbody"/>
      <child link="left_palm"/>
      <origin xyz="0.002 0.00144 0.03872" rpy="0.0 0.0 0.0"/>
   </joint>
   <link name="left_thumb_mp">
      <inertial>
         <origin xyz="-0.00247 0.0 0.004" rpy="0.0 -0.016249999999999876 0.0"/>
         <mass value="0.00586"/>
         <inertia ixx="8.4e-07" iyy="6.6e-07" izz="2.7e-07" ixy="0" ixz="0" iyz="0"/>
      </inertial>
      <visual name="left_visual_thumb_mp_mesh">
         <origin xyz="-0.00266727827583891 -3.661703007389301e-06 0.003202151013600351" rpy="-0.00450638440425983 0.0029041941261007675 0.0"/>
         <geometry>
            <mesh filename="package://orcahand_description/assets/urdf/left/visual/left_visual_thumb_mp_mesh.stl"/>
         </geometry>
         <material name="white"/>
      </visual>
      <collision name="left_collision_thumb_mp_mesh">
         <origin xyz="-0.0025186274059406425 1.1817094343651995e-05 0.0033325772179257297" rpy="-0.004051421860145692 0.0 0.0"/>
         <geometry>
            <mesh filename="package://orcahand_description/assets/urdf/left/collision/left_collision_thumb_mp_mesh.stl"/>
         </geometry>
         <material name="white"/>
      </collision>
   </link>
   <link name="left_thumb_mcp_jointbody">
      <inertial>
         <origin xyz="0.0 0.0 0.0" rpy="0.0 0.0 0.0"/>
         <mass value="0.001"/>
         <inertia ixx="1e-09" iyy="1e-09" izz="1e-09" ixy="0" ixz="0" iyz="0"/>
      </inertial>
   </link>
   <joint type="revolute" name="left_thumb_mcp">
      <parent link="left_palm"/>
      <child link="left_thumb_mcp_jointbody"/>
      <origin xyz="0.02821 0.01777 -0.01321" rpy="0.5385700000000002 0.055949999999999944 1.27047"/>
      <axis xyz="0.0 0.0 -1.0"/>
      <limit lower="-0.87266" upper="0.87266" effort="100" velocity="100"/>
   </joint>
   <joint type="fixed" name="left_thumb_mcp_offset">
      <parent link="left_thumb_mcp_jointbody"/>
      <child link="left_thumb_mp"/>
      <origin xyz="-0.0 -0.0 -0.0" rpy="0.0 0.0 0.0"/>
   </joint>
   <link name="left_thumb_pp">
      <inertial>
         <origin xyz="-0.01848 1e-05 2e-05" rpy="1.5707999999999998 -0.7739199999999998 -1.5708000000000002"/>
         <mass value="0.00655"/>
         <inertia ixx="7.5e-07" iyy="7.1e-07" izz="3e-07" ixy="0" ixz="0" iyz="0"/>
      </inertial>
      <visual name="left_visual_thumb_pp_mesh">
         <origin xyz="-0.01772057472979195 1.0070925191614406e-05 -0.0001049356891023396" rpy="-1.5398125854069626 -1.1287165327427522 -1.5983364234733113"/>
         <geometry>
            <mesh filename="package://orcahand_description/assets/urdf/left/visual/left_visual_thumb_pp_mesh.stl"/>
         </geometry>
         <material name="white"/>
      </visual>
      <collision name="left_collision_thumb_pp_mesh">
         <origin xyz="-0.017274731069872783 2.0812531064334347e-05 -0.00010892038972696928" rpy="-1.552700627717642 -1.351236091309624 -1.594202315837113"/>
         <geometry>
            <mesh filename="package://orcahand_description/assets/urdf/left/collision/left_collision_thumb_pp_mesh.stl"/>
         </geometry>
         <material name="white"/>
      </collision>
   </link>
   <link name="left_thumb_abd_jointbody">
      <inertial>
         <origin xyz="0.0 0.0 0.0" rpy="0.0 0.0 0.0"/>
         <mass value="0.001"/>
         <inertia ixx="1e-09" iyy="1e-09" izz="1e-09" ixy="0" ixz="0" iyz="0"/>
      </inertial>
   </link>
   <joint type="revolute" name="left_thumb_abd">
      <parent link="left_thumb_mp"/>
      <child link="left_thumb_abd_jointbody"/>
      <origin xyz="-6.938893903907228e-18 0.0 0.0" rpy="-1.22173 0.0 0.0"/>
      <axis xyz="0.0 -0.34202085907197166 -0.9396923602752502"/>
      <limit lower="-1.08211" upper="0.0" effort="100" velocity="100"/>
   </joint>
   <joint type="fixed" name="left_thumb_abd_offset">
      <parent link="left_thumb_abd_jointbody"/>
      <child link="left_thumb_pp"/>
      <origin xyz="0.03 -0.0 -0.0" rpy="0.0 0.0 0.0"/>
   </joint>
   <link name="left_thumb_ip">
      <inertial>
         <origin xyz="-0.00135 2e-05 0.01383" rpy="0.0003700000000000001 -0.03262999999999994 -0.00034"/>
         <mass value="0.01402"/>
         <inertia ixx="1.7e-06" iyy="1.64e-06" izz="5.9e-07" ixy="0" ixz="0" iyz="0"/>
      </inertial>
      <visual name="left_visual_thumb_ip_mesh">
         <origin xyz="-0.0012998948492342205 7.159773213648989e-06 0.013619877706625212" rpy="0.0 -0.04338716477372251 0.0"/>
         <geometry>
            <mesh filename="package://orcahand_description/assets/urdf/left/visual/left_visual_thumb_ip_mesh.stl"/>
         </geometry>
         <material name="white"/>
      </visual>
      <collision name="left_collision_thumb_ip_mesh">
         <origin xyz="-0.0013560375396256981 0.0001271082549174206 0.013446327660739957" rpy="0.00708255798627546 -0.04763590113115046 0.0"/>
         <geometry>
            <mesh filename="package://orcahand_description/assets/urdf/left/collision/left_collision_thumb_ip_mesh.stl"/>
         </geometry>
         <material name="white"/>
      </collision>
      <visual name="left_visual_thumb_ip_skin_mesh">
         <origin xyz="-0.0015424443589898442 1.6522252825528184e-07 0.01625964178517087" rpy="0.0 -1.2480960827956862 3.141592653589793"/>
         <geometry>
            <mesh filename="package://orcahand_description/assets/urdf/left/visual/left_visual_thumb_ip_skin_mesh.stl"/>
         </geometry>
         <material name="white"/>
      </visual>
      <collision name="left_collision_thumb_ip_skin_mesh">
         <origin xyz="-0.0015528244655451597 6.480724404306936e-06 0.01624665762187997" rpy="0.0 -1.2437718337020485 3.141592653589793"/>
         <geometry>
            <mesh filename="package://orcahand_description/assets/urdf/left/collision/left_collision_thumb_ip_skin_mesh.stl"/>
         </geometry>
         <material name="white"/>
      </collision>
   </link>
   <link name="left_thumb_pip_jointbody">
      <inertial>
         <origin xyz="0.0 0.0 0.0" rpy="0.0 0.0 0.0"/>
         <mass value="0.001"/>
         <inertia ixx="1e-09" iyy="1e-09" izz="1e-09" ixy="0" ixz="0" iyz="0"/>
      </inertial>
   </link>
   <joint type="revolute" name="left_thumb_pip">
      <parent link="left_thumb_pp"/>
      <child link="left_thumb_pip_jointbody"/>
      <origin xyz="0.0 0.0 0.0" rpy="-2.6535897934554242e-06 -1.5707926535897931 3.141592653589793"/>
      <axis xyz="0.0 1.0 0.0"/>
      <limit lower="-0.7944" upper="1.23" effort="100" velocity="100"/>
   </joint>
   <joint type="fixed" name="left_thumb_pip_offset">
      <parent link="left_thumb_pip_jointbody"/>
      <child link="left_thumb_ip"/>
      <origin xyz="-0.0 -0.0 -0.0" rpy="0.0 0.0 0.0"/>
   </joint>
   <link name="left_thumb_dp">
      <inertial>
         <origin xyz="-0.00233 1e-05 0.01133" rpy="0.00075 -0.0821099999999999 -0.00013000000000000002"/>
         <mass value="0.0132"/>
         <inertia ixx="1.4e-06" iyy="1.37e-06" izz="4.4e-07" ixy="0" ixz="0" iyz="0"/>
      </inertial>
      <visual name="left_visual_thumb_dp_mesh">
         <origin xyz="-0.0017376921197505616 -5.352917438125724e-06 0.005127321105400321" rpy="0.0 -0.24698289481892632 0.0"/>
         <geometry>
            <mesh filename="package://orcahand_description/assets/urdf/left/visual/left_visual_thumb_dp_mesh.stl"/>
         </geometry>
         <material name="white"/>
      </visual>
      <collision name="left_collision_thumb_dp_mesh">
         <origin xyz="-0.0020244971365026326 3.68319791392771e-05 0.005533677984084769" rpy="-0.24272423187789083 -0.008190712846545711 1.5728243710815684"/>
         <geometry>
            <mesh filename="package://orcahand_description/assets/urdf/left/collision/left_collision_thumb_dp_mesh.stl"/>
         </geometry>
         <material name="white"/>
      </collision>
      <visual name="left_visual_thumb_dp_skin_mesh">
         <origin xyz="-0.0027934355685519646 -6.143865554678962e-07 0.01660104201320062" rpy="3.141592653589793 -0.4023979327926315 0.0"/>
         <geometry>
            <mesh filename="package://orcahand_description/assets/urdf/left/visual/left_visual_thumb_dp_skin_mesh.stl"/>
         </geometry>
         <material name="white"/>
      </visual>
      <collision name="left_collision_thumb_dp_skin_mesh">
         <origin xyz="-0.0027854483360586716 -6.944475247259317e-06 0.016557497442018444" rpy="3.141592653589793 -0.3963953079219906 0.0"/>
         <geometry>
            <mesh filename="package://orcahand_description/assets/urdf/left/collision/left_collision_thumb_dp_skin_mesh.stl"/>
         </geometry>
         <material name="white"/>
      </collision>
   </link>
   <link name="left_thumb_dip_jointbody">
      <inertial>
         <origin xyz="0.0 0.0 0.0" rpy="0.0 0.0 0.0"/>
         <mass value="0.001"/>
         <inertia ixx="1e-09" iyy="1e-09" izz="1e-09" ixy="0" ixz="0" iyz="0"/>
      </inertial>
   </link>
   <joint type="revolute" name="left_thumb_dip">
      <parent link="left_thumb_ip"/>
      <child link="left_thumb_dip_jointbody"/>
      <origin xyz="0.0005 0.0 0.033" rpy="0.0 0.0 0.0"/>
      <axis xyz="0.0 -1.0 0.0"/>
      <limit lower="-0.85384" upper="1.45" effort="100" velocity="100"/>
   </joint>
   <joint type="fixed" name="left_thumb_dip_offset">
      <parent link="left_thumb_dip_jointbody"/>
      <child link="left_thumb_dp"/>
      <origin xyz="-0.0 -0.0 -0.0" rpy="0.0 0.0 0.0"/>
   </joint>
   <link name="left_thumb_fingertip">
      <inertial>
         <origin xyz="0.003 0.0 0.025" rpy="0.0 0.0 0.0"/>
         <mass value="0.0"/>
         <inertia ixx="0.0" iyy="0.0" izz="0.0" ixy="0" ixz="0" iyz="0"/>
      </inertial>
   </link>
   <joint type="fixed" name="thumb_dp2left_thumb_fingertip_fixed_offset">
      <parent link="left_thumb_dp"/>
      <child link="left_thumb_fingertip"/>
      <origin xyz="0.003 0.0 0.025" rpy="0.0 0.0 0.0"/>
   </joint>
   <link name="left_index_mp">
      <inertial>
         <origin xyz="-0.01155 0.0 -4e-05" rpy="-2.6535897934554242e-06 1.5707926535897934 3.141592653589793"/>
         <mass value="0.00498"/>
         <inertia ixx="3.4e-07" iyy="3.1e-07" izz="2e-07" ixy="0" ixz="0" iyz="0"/>
      </inertial>
      <visual name="left_visual_index_mp_mesh">
         <origin xyz="-0.010698479000335614 -1.3890654834761171e-05 -0.00027878809319396294" rpy="0.011821081396553579 -1.5066740246432395 3.1415926535897905"/>
         <geometry>
            <mesh filename="package://orcahand_description/assets/urdf/left/visual/left_visual_index_mp_mesh.stl"/>
         </geometry>
         <material name="white"/>
      </visual>
      <collision name="left_collision_index_mp_mesh">
         <origin xyz="-0.01047824184159959 -4.456734197189497e-05 -0.00016480462181888051" rpy="2.2133800120128084 -1.5147947849129795 0.9289651458686482"/>
         <geometry>
            <mesh filename="package://orcahand_description/assets/urdf/left/collision/left_collision_index_mp_mesh.stl"/>
         </geometry>
         <material name="white"/>
      </collision>
   </link>
   <link name="left_index_abd_jointbody">
      <inertial>
         <origin xyz="0.0 0.0 0.0" rpy="0.0 0.0 0.0"/>
         <mass value="0.001"/>
         <inertia ixx="1e-09" iyy="1e-09" izz="1e-09" ixy="0" ixz="0" iyz="0"/>
      </inertial>
   </link>
   <joint type="revolute" name="left_index_abd">
      <parent link="left_palm"/>
      <child link="left_index_abd_jointbody"/>
      <origin xyz="0.024088797002689358 0.0018999642829399502 0.025164928786148736" rpy="1.6066999999999996 -1.13552 0.05339000000000049"/>
      <axis xyz="0.0 0.0 1.0"/>
      <limit lower="-1.04577" upper="0.24577" effort="100" velocity="100"/>
   </joint>
   <joint type="fixed" name="left_index_abd_offset">
      <parent link="left_index_abd_jointbody"/>
      <child link="left_index_mp"/>
      <origin xyz="0.02 -0.0 -0.0" rpy="0.0 0.0 0.0"/>
   </joint>
   <link name="left_index_pp">
      <inertial>
         <origin xyz="-0.00135 2e-05 0.01637" rpy="0.00034 -0.020550000000000068 -0.00038"/>
         <mass value="0.0165"/>
         <inertia ixx="2.39e-06" iyy="2.31e-06" izz="7.1e-07" ixy="0" ixz="0" iyz="0"/>
      </inertial>
      <visual name="left_visual_index_pp_mesh">
         <origin xyz="-0.0012791981098529213 4.3222045694993146e-05 0.016098661080179" rpy="0.005516325755706635 -0.035101984887858206 -0.03910570256058449"/>
         <geometry>
            <mesh filename="package://orcahand_description/assets/urdf/left/visual/left_visual_index_pp_mesh.stl"/>
         </geometry>
         <material name="white"/>
      </visual>
      <collision name="left_collision_index_pp_mesh">
         <origin xyz="-0.001351674013134484 1.1247422892215279e-05 0.015681803525061735" rpy="0.0 -0.042883356216690816 0.0"/>
         <geometry>
            <mesh filename="package://orcahand_description/assets/urdf/left/collision/left_collision_index_pp_mesh.stl"/>
         </geometry>
         <material name="white"/>
      </collision>
      <visual name="left_visual_index_pp_skin_mesh">
         <origin xyz="-0.0016617007377281573 7.135678476891484e-08 0.018763861638214734" rpy="0.0 -0.8345404465359767 3.141592653589793"/>
         <geometry>
            <mesh filename="package://orcahand_description/assets/urdf/left/visual/left_visual_index_pp_skin_mesh.stl"/>
         </geometry>
         <material name="white"/>
      </visual>
      <collision name="left_collision_index_pp_skin_mesh">
         <origin xyz="-0.0016773866527582538 -5.531013170162649e-06 0.018740870134460887" rpy="0.0 -0.8259683678608112 3.141592653589793"/>
         <geometry>
            <mesh filename="package://orcahand_description/assets/urdf/left/collision/left_collision_index_pp_skin_mesh.stl"/>
         </geometry>
         <material name="white"/>
      </collision>
   </link>
   <link name="left_index_mcp_jointbody">
      <inertial>
         <origin xyz="0.0 0.0 0.0" rpy="0.0 0.0 0.0"/>
         <mass value="0.001"/>
         <inertia ixx="1e-09" iyy="1e-09" izz="1e-09" ixy="0" ixz="0" iyz="0"/>
      </inertial>
   </link>
   <joint type="revolute" name="left_index_mcp">
      <parent link="left_index_mp"/>
      <child link="left_index_mcp_jointbody"/>
      <origin xyz="0.0 0.0 0.0" rpy="3.141592653589793 1.5707926535897934 3.141592653589793"/>
      <axis xyz="0.0 -1.0 0.0"/>
      <limit lower="-0.34907" upper="1.65806" effort="100" velocity="100"/>
   </joint>
   <joint type="fixed" name="left_index_mcp_offset">
      <parent link="left_index_mcp_jointbody"/>
      <child link="left_index_pp"/>
      <origin xyz="-0.0 -0.0 -0.0" rpy="0.0 0.0 0.0"/>
   </joint>
   <link name="left_index_ip">
      <inertial>
         <origin xyz="-0.00071 1e-05 0.01929" rpy="-0.00042000000000000023 0.18549000000000015 -0.004400000000000001"/>
         <mass value="0.01521"/>
         <inertia ixx="2.08e-06" iyy="2.06e-06" izz="5.4e-07" ixy="0" ixz="0" iyz="0"/>
      </inertial>
      <visual name="left_visual_index_ip_mesh">
         <origin xyz="-0.001041679802592973 7.836534536637725e-05 0.011793743862640297" rpy="0.03448776902850703 -0.0034390239986910043 1.5706776757187162"/>
         <geometry>
            <mesh filename="package://orcahand_description/assets/urdf/left/visual/left_visual_index_ip_mesh.stl"/>
         </geometry>
         <material name="white"/>
      </visual>
      <collision name="left_collision_index_ip_mesh">
         <origin xyz="-0.0012645261424134968 -1.6371196153375355e-05 0.011472023264581544" rpy="-0.0018005943049513862 0.0 1.5707963267948966"/>
         <geometry>
            <mesh filename="package://orcahand_description/assets/urdf/left/collision/left_collision_index_ip_mesh.stl"/>
         </geometry>
         <material name="white"/>
      </collision>
      <visual name="left_visual_index_ip_skin_mesh">
         <origin xyz="-0.0006177579160319049 -2.8394632435326436e-07 0.02298191534250252" rpy="0.0 0.45635945417226464 0.0"/>
         <geometry>
            <mesh filename="package://orcahand_description/assets/urdf/left/visual/left_visual_index_ip_skin_mesh.stl"/>
         </geometry>
         <material name="white"/>
      </visual>
      <collision name="left_collision_index_ip_skin_mesh">
         <origin xyz="-0.0006216739383467691 2.4326074919833366e-06 0.023021049940676577" rpy="0.0 0.4457042297154219 0.0"/>
         <geometry>
            <mesh filename="package://orcahand_description/assets/urdf/left/collision/left_collision_index_ip_skin_mesh.stl"/>
         </geometry>
         <material name="white"/>
      </collision>
   </link>
   <link name="left_index_pip_jointbody">
      <inertial>
         <origin xyz="0.0 0.0 0.0" rpy="0.0 0.0 0.0"/>
         <mass value="0.001"/>
         <inertia ixx="1e-09" iyy="1e-09" izz="1e-09" ixy="0" ixz="0" iyz="0"/>
      </inertial>
   </link>
   <joint type="revolute" name="left_index_pip">
      <parent link="left_index_pp"/>
      <child link="left_index_pip_jointbody"/>
      <origin xyz="-0.0005 0.0 0.038" rpy="0.0 0.0 0.0"/>
      <axis xyz="0.0 1.0 0.0"/>
      <limit lower="-0.34907" upper="1.88496" effort="100" velocity="100"/>
   </joint>
   <joint type="fixed" name="left_index_pip_offset">
      <parent link="left_index_pip_jointbody"/>
      <child link="left_index_ip"/>
      <origin xyz="-0.0 -0.0 -0.0" rpy="0.0 0.0 0.0"/>
   </joint>
   <link name="left_index_fingertip">
      <inertial>
         <origin xyz="0.009 0.0 0.035" rpy="0.0 0.0 0.0"/>
         <mass value="0.0"/>
         <inertia ixx="0.0" iyy="0.0" izz="0.0" ixy="0" ixz="0" iyz="0"/>
      </inertial>
   </link>
   <joint type="fixed" name="left_index_ip2left_index_fingertip_fixed_offset">
      <parent link="left_index_ip"/>
      <child link="left_index_fingertip"/>
      <origin xyz="0.009 0.0 0.035" rpy="0.0 0.0 0.0"/>
   </joint>
   <link name="left_middle_mp">
      <inertial>
         <origin xyz="-0.01155 0.0 -4e-05" rpy="-2.6535897934554242e-06 1.5707926535897934 3.141592653589793"/>
         <mass value="0.00498"/>
         <inertia ixx="3.4e-07" iyy="3.1e-07" izz="2e-07" ixy="0" ixz="0" iyz="0"/>
      </inertial>
      <visual name="left_visual_middle_mp_mesh">
         <origin xyz="-0.010698479000335614 -1.389065483476104e-05 -0.00027878809319396294" rpy="3.1297715721932393 -1.5066740246432395 2.4424906541753444e-15"/>
         <geometry>
            <mesh filename="package://orcahand_description/assets/urdf/left/visual/left_visual_middle_mp_mesh.stl"/>
         </geometry>
         <material name="white"/>
      </visual>
      <collision name="left_collision_middle_mp_mesh">
         <origin xyz="-0.01047824184159959 -4.456734197189478e-05 -0.00016480462181888051" rpy="0.928212641576985 -1.5147947849129795 2.212627507721145"/>
         <geometry>
            <mesh filename="package://orcahand_description/assets/urdf/left/collision/left_collision_middle_mp_mesh.stl"/>
         </geometry>
         <material name="white"/>
      </collision>
   </link>
   <link name="left_middle_abd_jointbody">
      <inertial>
         <origin xyz="0.0 0.0 0.0" rpy="0.0 0.0 0.0"/>
         <mass value="0.001"/>
         <inertia ixx="1e-09" iyy="1e-09" izz="1e-09" ixy="0" ixz="0" iyz="0"/>
      </inertial>
   </link>
   <joint type="revolute" name="left_middle_abd">
      <parent link="left_palm"/>
      <child link="left_middle_abd_jointbody"/>
      <origin xyz="7.346410206776621e-08 0.0 0.030000000000134926" rpy="-1.5707926536208807 1.5707926535897934 3.141592653558706"/>
      <axis xyz="0.0 0.0 -1.0"/>
      <limit lower="-0.64577" upper="0.64577" effort="100" velocity="100"/>
   </joint>
   <joint type="fixed" name="left_middle_abd_offset">
      <parent link="left_middle_abd_jointbody"/>
      <child link="left_middle_mp"/>
      <origin xyz="0.02 -0.0 -0.0" rpy="0.0 0.0 0.0"/>
   </joint>
   <link name="left_middle_pp">
      <inertial>
         <origin xyz="-0.00144 2e-05  0.02021" rpy="-2.9999999999999916e-05 -0.013859999999999983 -0.0005999999999999998"/>
         <mass value="0.02006"/>
         <inertia ixx="3.78e-06" iyy="3.69e-06" izz="8.9e-07" ixy="0" ixz="0" iyz="0"/>
      </inertial>
      <visual name="left_visual_middle_pp_mesh">
         <origin xyz="-0.0012834219301920448 3.69633426842407e-05 0.020227207759531022" rpy="0.004564296284170381 -0.02765637633446838 -0.037580505677349094"/>
         <geometry>
            <mesh filename="package://orcahand_description/assets/urdf/left/visual/left_visual_middle_pp_mesh.stl"/>
         </geometry>
         <material name="white"/>
      </visual>
      <collision name="left_collision_middle_pp_mesh">
         <origin xyz="-0.0013393807706560765 -6.845101857801819e-06 0.02011933923689832" rpy="-0.0006410664486678006 -0.029880005436222712 5.421010862427522e-20"/>
         <geometry>
            <mesh filename="package://orcahand_description/assets/urdf/left/collision/left_collision_middle_pp_mesh.stl"/>
         </geometry>
         <material name="white"/>
      </collision>
      <visual name="left_visual_middle_pp_skin_mesh">
         <origin xyz="-0.0017296991161894423 2.0144468928870053e-08 0.02293828897793899" rpy="0.0 0.22312530126971986 0.0"/>
         <geometry>
            <mesh filename="package://orcahand_description/assets/urdf/left/visual/left_visual_middle_pp_skin_mesh.stl"/>
         </geometry>
         <material name="white"/>
      </visual>
      <collision name="left_collision_middle_pp_skin_mesh">
         <origin xyz="-0.0017525848624676125 2.7252940732880306e-06 0.022885135333659" rpy="0.0 0.220060617673979 0.0"/>
         <geometry>
            <mesh filename="package://orcahand_description/assets/urdf/left/collision/left_collision_middle_pp_skin_mesh.stl"/>
         </geometry>
         <material name="white"/>
      </collision>
   </link>
   <link name="left_middle_mcp_jointbody">
      <inertial>
         <origin xyz="0.0 0.0 0.0" rpy="0.0 0.0 0.0"/>
         <mass value="0.001"/>
         <inertia ixx="1e-09" iyy="1e-09" izz="1e-09" ixy="0" ixz="0" iyz="0"/>
      </inertial>
   </link>
   <joint type="revolute" name="left_middle_mcp">
      <parent link="left_middle_mp"/>
      <child link="left_middle_mcp_jointbody"/>
      <origin xyz="0.0 0.0 0.0" rpy="3.141592653589793 1.5707926535897934 3.141592653589793"/>
      <axis xyz="0.0 -1.0 0.0"/>
      <limit lower="-0.34907" upper="1.58825" effort="100" velocity="100"/>
   </joint>
   <joint type="fixed" name="left_middle_mcp_offset">
      <parent link="left_middle_mcp_jointbody"/>
      <child link="left_middle_pp"/>
      <origin xyz="-0.0 -0.0 -0.0" rpy="0.0 0.0 0.0"/>
   </joint>
   <link name="left_middle_ip">
      <inertial>
         <origin xyz="-0.00071 1e-05 0.01929" rpy="-0.00042000000000000023 0.18549000000000015 -0.004400000000000001"/>
         <mass value="0.01521"/>
         <inertia ixx="2.08e-06" iyy="2.06e-06" izz="5.4e-07" ixy="0" ixz="0" iyz="0"/>
      </inertial>
      <visual name="left_visual_middle_ip_mesh">
         <origin xyz="-0.001041679802592973 7.836534536637725e-05 0.011793743862640297" rpy="0.03448776902850703 -0.0034390239986910043 1.5706776757187162"/>
         <geometry>
            <mesh filename="package://orcahand_description/assets/urdf/left/visual/left_visual_middle_ip_mesh.stl"/>
         </geometry>
         <material name="white"/>
      </visual>
      <collision name="left_collision_middle_ip_mesh">
         <origin xyz="-0.0012645261424134968 -1.6371196153375355e-05 0.011472023264581544" rpy="-0.0018005943049513862 0.0 1.5707963267948966"/>
         <geometry>
            <mesh filename="package://orcahand_description/assets/urdf/left/collision/left_collision_middle_ip_mesh.stl"/>
         </geometry>
         <material name="white"/>
      </collision>
      <visual name="left_visual_middle_ip_skin_mesh">
         <origin xyz="-0.0006177579160319049 -2.8394632435326436e-07 0.02298191534250252" rpy="0.0 0.45635945417226464 0.0"/>
         <geometry>
            <mesh filename="package://orcahand_description/assets/urdf/left/visual/left_visual_middle_ip_skin_mesh.stl"/>
         </geometry>
         <material name="white"/>
      </visual>
      <collision name="left_collision_middle_ip_skin_mesh">
         <origin xyz="-0.0006216739383467691 2.4326074919833366e-06 0.023021049940676577" rpy="0.0 0.4457042297154219 0.0"/>
         <geometry>
            <mesh filename="package://orcahand_description/assets/urdf/left/collision/left_collision_middle_ip_skin_mesh.stl"/>
         </geometry>
         <material name="white"/>
      </collision>
   </link>
   <link name="left_middle_pip_jointbody">
      <inertial>
         <origin xyz="0.0 0.0 0.0" rpy="0.0 0.0 0.0"/>
         <mass value="0.001"/>
         <inertia ixx="1e-09" iyy="1e-09" izz="1e-09" ixy="0" ixz="0" iyz="0"/>
      </inertial>
   </link>
   <joint type="revolute" name="left_middle_pip">
      <parent link="left_middle_pp"/>
      <child link="left_middle_pip_jointbody"/>
      <origin xyz="0.0 0.0 0.0" rpy="-2.6535897934554242e-06 -1.5707926535897931 3.141592653589793"/>
      <axis xyz="0.0 1.0 0.0"/>
      <limit lower="-0.34907" upper="1.8675" effort="100" velocity="100"/>
   </joint>
   <joint type="fixed" name="left_middle_pip_offset">
      <parent link="left_middle_pip_jointbody"/>
      <child link="left_middle_ip"/>
      <origin xyz="-0.0 -0.0 -0.0" rpy="0.0 0.0 0.0"/>
   </joint>
      <link name="left_middle_fingertip">
      <inertial>
         <origin xyz="-0.009 0.0 0.035" rpy="0.0 0.0 0.0"/>
         <mass value="0.0"/>
         <inertia ixx="0.0" iyy="0.0" izz="0.0" ixy="0" ixz="0" iyz="0"/>
      </inertial>
   </link>
   <joint type="fixed" name="left_middle_ip2left_index_fingertip_fixed_offset">
      <parent link="left_middle_ip"/>
      <child link="left_middle_fingertip"/>
      <origin xyz="-0.009 0.0 0.035" rpy="0.0 0.0 0.0"/>
   </joint>
   <link name="left_ring_mp">
      <inertial>
         <origin xyz="-0.01155 0.0 -4e-05" rpy="-2.6535897932333796e-06 1.5707926535897934 3.141592653589793"/>
         <mass value="0.00498"/>
         <inertia ixx="3.4e-07" iyy="3.1e-07" izz="2e-07" ixy="0" ixz="0" iyz="0"/>
      </inertial>
      <visual name="left_visual_ring_mp_mesh">
         <origin xyz="-0.010698479000335614 -1.389065483476104e-05 -0.00027878809319396294" rpy="3.1297715721932393 -1.5066740246432395 2.4424906541753444e-15"/>
         <geometry>
            <mesh filename="package://orcahand_description/assets/urdf/left/visual/left_visual_ring_mp_mesh.stl"/>
         </geometry>
         <material name="white"/>
      </visual>
      <collision name="left_collision_ring_mp_mesh">
         <origin xyz="-0.01047824184159959 -4.456734197189478e-05 -0.00016480462181888051" rpy="0.928212641576985 -1.5147947849129795 2.212627507721145"/>
         <geometry>
            <mesh filename="package://orcahand_description/assets/urdf/left/collision/left_collision_ring_mp_mesh.stl"/>
         </geometry>
         <material name="white"/>
      </collision>
   </link>
   <link name="left_ring_abd_jointbody">
      <inertial>
         <origin xyz="0.0 0.0 0.0" rpy="0.0 0.0 0.0"/>
         <mass value="0.001"/>
         <inertia ixx="1e-09" iyy="1e-09" izz="1e-09" ixy="0" ixz="0" iyz="0"/>
      </inertial>
   </link>
   <joint type="revolute" name="left_ring_abd">
      <parent link="left_palm"/>
      <child link="left_ring_abd_jointbody"/>
      <origin xyz="-0.021521022061295733 0.0015382095479525787 0.020824784431525818" rpy="-1.5359699999999994 -1.30836 3.0544099999999994"/>
      <axis xyz="0.0 0.0 -1.0"/>
      <limit lower="-0.47577" upper="0.80577" effort="100" velocity="100"/>
   </joint>
   <joint type="fixed" name="left_ring_abd_offset">
      <parent link="left_ring_abd_jointbody"/>
      <child link="left_ring_mp"/>
      <origin xyz="0.02 -0.0 -0.0" rpy="0.0 0.0 0.0"/>
   </joint>
   <link name="left_ring_pp">
      <inertial>
         <origin xyz="-0.00144 2e-05 0.02021" rpy="-2.9999999999999916e-05 -0.013859999999999983 -0.0005999999999999998"/>
         <mass value="0.02006"/>
         <inertia ixx="3.78e-06" iyy="3.69e-06" izz="8.9e-07" ixy="0" ixz="0" iyz="0"/>
      </inertial>
      <visual name="left_visual_ring_pp_mesh">
         <origin xyz="-0.0012834219301920448 3.69633426842407e-05 0.020227207759531022" rpy="0.004564296284170381 -0.02765637633446838 -0.037580505677349094"/>
         <geometry>
            <mesh filename="package://orcahand_description/assets/urdf/left/visual/left_visual_ring_pp_mesh.stl"/>
         </geometry>
         <material name="white"/>
      </visual>
      <collision name="left_collision_ring_pp_mesh">
         <origin xyz="-0.0013393807706560765 -6.845101857801819e-06 0.02011933923689832" rpy="-0.0006410664486678006 -0.029880005436222712 5.421010862427522e-20"/>
         <geometry>
            <mesh filename="package://orcahand_description/assets/urdf/left/collision/left_collision_ring_pp_mesh.stl"/>
         </geometry>
         <material name="white"/>
      </collision>
      <visual name="left_visual_ring_pp_skin_mesh">
         <origin xyz="-0.0017296991161894423 2.0144468928870053e-08 0.02293828897793899" rpy="0.0 0.22312530126971986 0.0"/>
         <geometry>
            <mesh filename="package://orcahand_description/assets/urdf/left/visual/left_visual_ring_pp_skin_mesh.stl"/>
         </geometry>
         <material name="white"/>
      </visual>
      <collision name="left_collision_ring_pp_skin_mesh">
         <origin xyz="-0.0017525848624676125 2.7252940732880306e-06 0.022885135333659" rpy="0.0 0.220060617673979 0.0"/>
         <geometry>
            <mesh filename="package://orcahand_description/assets/urdf/left/collision/left_collision_ring_pp_skin_mesh.stl"/>
         </geometry>
         <material name="white"/>
      </collision>
   </link>
   <link name="left_ring_mcp_jointbody">
      <inertial>
         <origin xyz="0.0 0.0 0.0" rpy="0.0 0.0 0.0"/>
         <mass value="0.001"/>
         <inertia ixx="1e-09" iyy="1e-09" izz="1e-09" ixy="0" ixz="0" iyz="0"/>
      </inertial>
   </link>
   <joint type="revolute" name="left_ring_mcp">
      <parent link="left_ring_mp"/>
      <child link="left_ring_mcp_jointbody"/>
      <origin xyz="0.0 0.0 0.0" rpy="3.141592653589793 -1.5707926535897931 3.141592653589793"/>
      <axis xyz="0.0 -1.0 0.0"/>
      <limit lower="-0.34907" upper="1.58825" effort="100" velocity="100"/>
   </joint>
   <joint type="fixed" name="left_ring_mcp_offset">
      <parent link="left_ring_mcp_jointbody"/>
      <child link="left_ring_pp"/>
      <origin xyz="-0.0 -0.0 -0.0" rpy="0.0 0.0 0.0"/>
   </joint>
   <link name="left_ring_ip">
      <inertial>
         <origin xyz="-0.00071 1e-05 0.01929" rpy="-0.00042000000000000023 0.18549000000000015 -0.004400000000000001"/>
         <mass value="0.01521"/>
         <inertia ixx="2.08e-06" iyy="2.06e-06" izz="5.4e-07" ixy="0" ixz="0" iyz="0"/>
      </inertial>
      <visual name="left_visual_ring_ip_mesh">
         <origin xyz="-0.001041679802592973 7.836534536637725e-05 0.011793743862640297" rpy="0.03448776902850703 -0.0034390239986910043 1.5706776757187162"/>
         <geometry>
            <mesh filename="package://orcahand_description/assets/urdf/left/visual/left_visual_ring_ip_mesh.stl"/>
         </geometry>
         <material name="white"/>
      </visual>
      <collision name="left_collision_ring_ip_mesh">
         <origin xyz="-0.0012645261424134968 -1.6371196153375355e-05 0.011472023264581544" rpy="-0.0018005943049513862 0.0 1.5707963267948966"/>
         <geometry>
            <mesh filename="package://orcahand_description/assets/urdf/left/collision/left_collision_ring_ip_mesh.stl"/>
         </geometry>
         <material name="white"/>
      </collision>
      <visual name="left_visual_ring_ip_skin_mesh">
         <origin xyz="-0.0006177579160319049 -2.8394632435326436e-07 0.02298191534250252" rpy="0.0 -0.45635945417226464 0.0"/>
         <geometry>
            <mesh filename="package://orcahand_description/assets/urdf/left/visual/left_visual_ring_ip_skin_mesh.stl"/>
         </geometry>
         <material name="white"/>
      </visual>
      <collision name="left_collision_ring_ip_skin_mesh">
         <origin xyz="-0.0006216739383467691 2.4326074919833366e-06 0.023021049940676577" rpy="0.0 -0.4457042297154219 0.0"/>
         <geometry>
            <mesh filename="package://orcahand_description/assets/urdf/left/collision/left_collision_ring_ip_skin_mesh.stl"/>
         </geometry>
         <material name="white"/>
      </collision>
   </link>
   <link name="left_ring_pip_jointbody">
      <inertial>
         <origin xyz="0.0 0.0 0.0" rpy="0.0 0.0 0.0"/>
         <mass value="0.001"/>
         <inertia ixx="1e-09" iyy="1e-09" izz="1e-09" ixy="0" ixz="0" iyz="0"/>
      </inertial>
   </link>
   <joint type="revolute" name="left_ring_pip">
      <parent link="left_ring_pp"/>
      <child link="left_ring_pip_jointbody"/>
      <origin xyz="-0.0005 0.0 0.046" rpy="0.0 0.0 0.0"/>
      <axis xyz="0.0 -1.0 0.0"/>
      <limit lower="-0.34907" upper="1.8675" effort="100" velocity="100"/>
   </joint>
   <joint type="fixed" name="left_ring_pip_offset">
      <parent link="left_ring_pip_jointbody"/>
      <child link="left_ring_ip"/>
      <origin xyz="-0.0 -0.0 -0.0" rpy="0.0 0.0 0.0"/>
   </joint>
   <link name="left_ring_fingertip">
      <inertial>
         <origin xyz="0.003 0.0 0.025" rpy="0.0 0.0 0.0"/>
         <mass value="0.0"/>
         <inertia ixx="0.0" iyy="0.0" izz="0.0" ixy="0" ixz="0" iyz="0"/>
      </inertial>
   </link>
   <joint type="fixed" name="left_ring_ip2left_index_fingertip_fixed_offset">
      <parent link="left_ring_ip"/>
      <child link="left_ring_fingertip"/>
      <origin xyz="0.003 0.0 0.025" rpy="0.0 0.0 0.0"/>
   </joint>

  <!-- ========================================= -->
  <!-- RIGHT ORCA HAND EXTENDED - COMPLETE INLINE -->
  <!-- ALL content from orcahand_right_extended.urdf -->
  <!-- ========================================= -->
  
  <link name="right_tower">
      <inertial>
         <origin xyz="0.04034 -0.00091 0.01912" rpy="-0.0026099999999999977 0.007370000000000099 0.04145"/>
         <mass value="0.9"/>
         <inertia ixx="0.00150422" iyy="0.00125262" izz="0.0007962" ixy="0" ixz="0" iyz="0"/>
      </inertial>
      <visual name="right_visual_tower_main_mesh">
         <origin xyz="0.04069509610470536 -0.00012511806280993186 0.02312294830988657" rpy="-0.007252153364137093 -0.004356332895580239 1.533990149039079"/>
         <geometry>
            <mesh filename="package://orcahand_description/assets/urdf/right/visual/right_visual_tower_main_mesh.stl"/>
         </geometry>
         <material name="white"/>
      </visual>
      <collision name="right_collision_tower_main_mesh">
         <origin xyz="0.041026105966065735 0.0008755408110132971 0.03758955025925282" rpy="0.0663641604020242 -0.10532695421927696 -0.7765909134463538"/>
         <geometry>
            <mesh filename="package://orcahand_description/assets/urdf/right/collision/right_collision_tower_main_mesh.stl"/>
         </geometry>
         <material name="white"/>
      </collision>
      <visual name="right_visual_tower_hull_mesh">
         <origin xyz="0.04062006698890873 -3.726678941555769e-06 0.009339292204050375" rpy="1.5694791585075034 0.00015194814647356836 -0.0006505124711437826"/>
         <geometry>
            <mesh filename="package://orcahand_description/assets/urdf/right/visual/right_visual_tower_hull_mesh.stl"/>
         </geometry>
         <material name="white"/>
      </visual>
      <collision name="right_collision_tower_hull_mesh">
         <origin xyz="0.04061884697236149 7.083739226185091e-06 0.009306225228503611" rpy="1.5691929949477865 -6.931644826568828e-05 -0.0012916867662787768"/>
         <geometry>
            <mesh filename="package://orcahand_description/assets/urdf/right/collision/right_collision_tower_hull_mesh.stl"/>
         </geometry>
         <material name="white"/>
      </collision>
      <visual name="right_visual_tower_text_mesh">
         <origin xyz="0.040617526582081696 4.362558106779257e-06 0.02737731026837054" rpy="8.992806499463768e-14 -1.570241143557443 1.5988186561911613"/>
         <geometry>
            <mesh filename="package://orcahand_description/assets/urdf/right/visual/right_visual_tower_text_mesh.stl"/>
         </geometry>
         <material name="white"/>
      </visual>
      <collision name="right_collision_tower_text_mesh">
         <origin xyz="0.04068345506360967 -0.0011250828560853416 0.027716099517902396" rpy="-2.239658800831686 -1.5545672668594075 -2.4480790171423275"/>
         <geometry>
            <mesh filename="package://orcahand_description/assets/urdf/right/collision/right_collision_tower_text_mesh.stl"/>
         </geometry>
         <material name="white"/>
      </collision>
      <visual name="right_visual_tower_fans_mesh">
         <origin xyz="0.0937464851642263 -7.333906795588065e-05 0.007302881628386407" rpy="0.007368589590845024 0.003155430003398685 0.002439910618462611"/>
         <geometry>
            <mesh filename="package://orcahand_description/assets/urdf/right/visual/right_visual_tower_fans_mesh.stl"/>
         </geometry>
         <material name="white"/>
      </visual>
      <collision name="right_collision_tower_fans_mesh">
         <origin xyz="0.09363557490715463 -8.389280125979868e-05 0.007667379216642167" rpy="0.005482193788632295 0.004072983473719427 -0.007158680095836076"/>
         <geometry>
            <mesh filename="package://orcahand_description/assets/urdf/right/collision/right_collision_tower_fans_mesh.stl"/>
         </geometry>
         <material name="white"/>
      </collision>
      <visual name="right_visual_tower_u2d2_mesh">
         <origin xyz="-0.012411919130245945 0.0016444826825456232 -0.017176262543363695" rpy="1.9248601461816697 0.03942618910803675 0.09532348749637565"/>
         <geometry>
            <mesh filename="package://orcahand_description/assets/urdf/right/visual/right_visual_tower_u2d2_mesh.stl"/>
         </geometry>
         <material name="white"/>
      </visual>
      <collision name="right_collision_tower_u2d2_mesh">
         <origin xyz="-0.010637828550943964 0.00323315623973064 -0.016564434073768834" rpy="1.9254973571203653 -0.010117808892087687 0.1004013246446912"/>
         <geometry>
            <mesh filename="package://orcahand_description/assets/urdf/right/collision/right_collision_tower_u2d2_mesh.stl"/>
         </geometry>
         <material name="white"/>
      </collision>
      <visual name="right_visual_tower_camera_mesh">
         <origin xyz="0.04141561887638722 0.052825801794652016 -0.019856742052109723" rpy="-3.066013393320364 -1.0811766886677918 -1.6762365509261419"/>
         <geometry>
            <mesh filename="package://orcahand_description/assets/urdf/right/visual/right_visual_tower_camera_mesh.stl"/>
         </geometry>
         <material name="white"/>
      </visual>
      <collision name="right_collision_tower_camera_mesh">
         <origin xyz="0.042893192852471285 0.07588858343086753 -0.0036651034799500375" rpy="1.1260913945251536 -1.3561455079929272 1.9214250245447837"/>
         <geometry>
            <mesh filename="package://orcahand_description/assets/urdf/right/collision/right_collision_tower_camera_mesh.stl"/>
         </geometry>
         <material name="white"/>
      </collision>
   </link>
   <link name="right_palm">
      <inertial>
         <origin xyz="0.00193 -0.00052 -0.00664" rpy="1.67519 0.04750000000000032 1.55556"/>
         <mass value="0.0257"/>
         <inertia ixx="1.612e-05" iyy="1.151e-05" izz="6.72e-06" ixy="0" ixz="0" iyz="0"/>
      </inertial>
      <visual name="right_visual_palm_mesh">
         <origin xyz="0.0015568393804010381 0.00032366355975666324 -0.011896430343868667" rpy="2.01172521777585 0.047179539585598285 1.531383022156099"/>
         <geometry>
            <mesh filename="package://orcahand_description/assets/urdf/right/visual/right_visual_palm_mesh.stl"/>
         </geometry>
         <material name="white"/>
      </visual>
      <collision name="right_collision_palm_mesh">
         <origin xyz="0.0015796019462848588 0.0001376248446814945 -0.011923873250196919" rpy="2.026338195778868 0.044917456181218895 1.531847751735018"/>
         <geometry>
            <mesh filename="package://orcahand_description/assets/urdf/right/collision/right_collision_palm_mesh.stl"/>
         </geometry>
         <material name="white"/>
      </collision>
      <visual name="right_visual_palm_skin_mesh">
         <origin xyz="0.005673309514830851 -0.0012702684906836111 -0.001744430321194409" rpy="1.7666058493725336 0.1563942094199331 1.6505205003593353"/>
         <geometry>
            <mesh filename="package://orcahand_description/assets/urdf/right/visual/right_visual_palm_skin_mesh.stl"/>
         </geometry>
         <material name="white"/>
      </visual>
      <collision name="right_collision_palm_skin_mesh">
         <origin xyz="0.008013832397891144 -0.001293701510845759 -0.0015696747425978242" rpy="1.8840619193629062 0.16785003095386486 1.6839920915628581"/>
         <geometry>
            <mesh filename="package://orcahand_description/assets/urdf/right/collision/right_collision_palm_skin_mesh.stl"/>
         </geometry>
         <material name="white"/>
      </collision>
   </link>
   <link name="right_wrist_jointbody">
      <inertial>
         <origin xyz="0.0 0.0 0.0" rpy="0.0 0.0 0.0"/>
         <mass value="0.001"/>
         <inertia ixx="1e-09" iyy="1e-09" izz="1e-09" ixy="0" ixz="0" iyz="0"/>
      </inertial>
   </link>
   <joint type="revolute" name="right_wrist">
      <parent link="right_tower"/>
      <child link="right_wrist_jointbody"/>
      <origin xyz="0.04063 0.0 0.10486999999999999" rpy="0.0 0.0 0.0"/>
      <axis xyz="1.0 0.0 0.0"/>
      <limit lower="-0.6736" upper="0.8972" effort="100" velocity="100"/>
   </joint>
   <joint type="fixed" name="right_wrist_offset">
      <parent link="right_wrist_jointbody"/>
      <child link="right_palm"/>
      <origin xyz="-0.002 0.00144 0.03872" rpy="0.0 0.0 0.0"/>
   </joint>
   <link name="right_thumb_mp">
      <inertial>
         <origin xyz="0.00247 0.0 0.004" rpy="0.0 0.016249999999999876 0.0"/>
         <mass value="0.00586"/>
         <inertia ixx="8.4e-07" iyy="6.6e-07" izz="2.7e-07" ixy="0" ixz="0" iyz="0"/>
      </inertial>
      <visual name="right_visual_thumb_mp_mesh">
         <origin xyz="0.0026672782758389094 -3.6617030073895996e-06 0.0032021510136003503" rpy="-0.00450638440425983 -0.0029041941261005455 0.0"/>
         <geometry>
            <mesh filename="package://orcahand_description/assets/urdf/right/visual/right_visual_thumb_mp_mesh.stl"/>
         </geometry>
         <material name="white"/>
      </visual>
      <collision name="right_collision_thumb_mp_mesh">
         <origin xyz="0.0025186274059406416 1.1817094343651893e-05 0.0033325772179257306" rpy="-0.004051421860145692 0.0 0.0"/>
         <geometry>
            <mesh filename="package://orcahand_description/assets/urdf/right/collision/right_collision_thumb_mp_mesh.stl"/>
         </geometry>
         <material name="white"/>
      </collision>
   </link>
   <link name="right_thumb_mcp_jointbody">
      <inertial>
         <origin xyz="0.0 0.0 0.0" rpy="0.0 0.0 0.0"/>
         <mass value="0.001"/>
         <inertia ixx="1e-09" iyy="1e-09" izz="1e-09" ixy="0" ixz="0" iyz="0"/>
      </inertial>
   </link>
   <joint type="revolute" name="right_thumb_mcp">
      <parent link="right_palm"/>
      <child link="right_thumb_mcp_jointbody"/>
      <origin xyz="-0.02821 0.01777 -0.01321" rpy="0.5385700000000002 -0.05594999999999972 -1.27047"/>
      <axis xyz="0.0 0.0 -1.0"/>
      <limit lower="-0.87266" upper="0.87266" effort="100" velocity="100"/>
   </joint>
   <joint type="fixed" name="right_thumb_mcp_offset">
      <parent link="right_thumb_mcp_jointbody"/>
      <child link="right_thumb_mp"/>
      <origin xyz="-0.0 -0.0 -0.0" rpy="0.0 0.0 0.0"/>
   </joint>
   <link name="right_thumb_pp">
      <inertial>
         <origin xyz="0.01848 1e-05 2e-05" rpy="1.5708 0.7739199999999999 1.5708"/>
         <mass value="0.00655"/>
         <inertia ixx="7.5e-07" iyy="7.1e-07" izz="3e-07" ixy="0" ixz="0" iyz="0"/>
      </inertial>
      <visual name="right_visual_thumb_pp_mesh">
         <origin xyz="0.01772057472979195 1.0070925191614284e-05 -0.00010493568910233946" rpy="-1.6017800681828298 -1.1287165327427504 -1.5432562301164818"/>
         <geometry>
            <mesh filename="package://orcahand_description/assets/urdf/right/visual/right_visual_thumb_pp_mesh.stl"/>
         </geometry>
         <material name="white"/>
      </visual>
      <collision name="right_collision_thumb_pp_mesh">
         <origin xyz="0.01727473106987278 2.0812531064334476e-05 -0.00010892038972696916" rpy="-1.588892025872152 -1.3512360913096229 -1.5473903377526785"/>
         <geometry>
            <mesh filename="package://orcahand_description/assets/urdf/right/collision/right_collision_thumb_pp_mesh.stl"/>
         </geometry>
         <material name="white"/>
      </collision>
   </link>
   <link name="right_thumb_abd_jointbody">
      <inertial>
         <origin xyz="0.0 0.0 0.0" rpy="0.0 0.0 0.0"/>
         <mass value="0.001"/>
         <inertia ixx="1e-09" iyy="1e-09" izz="1e-09" ixy="0" ixz="0" iyz="0"/>
      </inertial>
   </link>
   <joint type="revolute" name="right_thumb_abd">
      <parent link="right_thumb_mp"/>
      <child link="right_thumb_abd_jointbody"/>
      <origin xyz="6.938893903907228e-18 0.0 0.0" rpy="-1.22173 0.0 0.0"/>
      <axis xyz="0.0 0.34202085907197166 0.9396923602752502"/>
      <limit lower="-1.08211" upper="0.0" effort="100" velocity="100"/>
   </joint>
   <joint type="fixed" name="right_thumb_abd_offset">
      <parent link="right_thumb_abd_jointbody"/>
      <child link="right_thumb_pp"/>
      <origin xyz="-0.03 -0.0 -0.0" rpy="0.0 0.0 0.0"/>
   </joint>
   <link name="right_thumb_ip">
      <inertial>
         <origin xyz="0.00135 2e-05 0.01383" rpy="0.0003700000000000001 0.03263000000000016 0.00034"/>
         <mass value="0.01402"/>
         <inertia ixx="1.7e-06" iyy="1.64e-06" izz="5.9e-07" ixy="0" ixz="0" iyz="0"/>
      </inertial>
      <visual name="right_visual_thumb_ip_mesh">
         <origin xyz="0.0012998948492342203 7.159773213648307e-06 0.013619877706625217" rpy="0.0 0.04338716477372251 0.0"/>
         <geometry>
            <mesh filename="package://orcahand_description/assets/urdf/right/visual/right_visual_thumb_ip_mesh.stl"/>
         </geometry>
         <material name="white"/>
      </visual>
      <collision name="right_collision_thumb_ip_mesh">
         <origin xyz="0.0013560375396256981 0.00012710825491742077 0.013446327660739959" rpy="0.00708255798627546 0.04763590113115046 0.0"/>
         <geometry>
            <mesh filename="package://orcahand_description/assets/urdf/right/collision/right_collision_thumb_ip_mesh.stl"/>
         </geometry>
         <material name="white"/>
      </collision>
      <visual name="right_visual_thumb_ip_skin_mesh">
         <origin xyz="0.0015424443589898442 1.6522252825510055e-07 0.016259641785170875" rpy="3.141592653589793 -1.2480960827956862 0.0"/>
         <geometry>
            <mesh filename="package://orcahand_description/assets/urdf/right/visual/right_visual_thumb_ip_skin_mesh.stl"/>
         </geometry>
         <material name="white"/>
      </visual>
      <collision name="right_collision_thumb_ip_skin_mesh">
         <origin xyz="0.0015528244655451595 6.48072440430664e-06 0.016246657621879965" rpy="3.141592653589793 -1.243771833702049 0.0"/>
         <geometry>
            <mesh filename="package://orcahand_description/assets/urdf/right/collision/right_collision_thumb_ip_skin_mesh.stl"/>
         </geometry>
         <material name="white"/>
      </collision>
   </link>
   <link name="right_thumb_pip_jointbody">
      <inertial>
         <origin xyz="0.0 0.0 0.0" rpy="0.0 0.0 0.0"/>
         <mass value="0.001"/>
         <inertia ixx="1e-09" iyy="1e-09" izz="1e-09" ixy="0" ixz="0" iyz="0"/>
      </inertial>
   </link>
   <joint type="revolute" name="right_thumb_pip">
      <parent link="right_thumb_pp"/>
      <child link="right_thumb_pip_jointbody"/>
      <origin xyz="0.0 0.0 0.0" rpy="-2.6535897934554242e-06 1.5707926535897934 3.141592653589793"/>
      <axis xyz="0.0 -1.0 0.0"/>
      <limit lower="-0.7944" upper="1.23" effort="100" velocity="100"/>
   </joint>
   <joint type="fixed" name="right_thumb_pip_offset">
      <parent link="right_thumb_pip_jointbody"/>
      <child link="right_thumb_ip"/>
      <origin xyz="-0.0 -0.0 -0.0" rpy="0.0 0.0 0.0"/>
   </joint>
   <link name="right_thumb_dp">
      <inertial>
         <origin xyz="0.00233 1e-05 0.01133" rpy="0.00075 0.08211000000000013 0.00013000000000000002"/>
         <mass value="0.0132"/>
         <inertia ixx="1.4e-06" iyy="1.37e-06" izz="4.4e-07" ixy="0" ixz="0" iyz="0"/>
      </inertial>
      <visual name="right_visual_thumb_dp_mesh">
         <origin xyz="0.001737692119750562 -5.352917438125722e-06 0.005127321105400321" rpy="0.0 0.24698289481892632 0.0"/>
         <geometry>
            <mesh filename="package://orcahand_description/assets/urdf/right/visual/right_visual_thumb_dp_mesh.stl"/>
         </geometry>
         <material name="white"/>
      </visual>
      <collision name="right_collision_thumb_dp_mesh">
         <origin xyz="0.0020244971365026335 3.68319791392775e-05 0.005533677984084769" rpy="0.24272423187789072 -0.008190712846545711 1.5687682825082248"/>
         <geometry>
            <mesh filename="package://orcahand_description/assets/urdf/right/collision/right_collision_thumb_dp_mesh.stl"/>
         </geometry>
         <material name="white"/>
      </collision>
      <visual name="right_visual_thumb_dp_skin_mesh">
         <origin xyz="0.002793435568551968 -6.14386555467744e-07 0.016601042013200628" rpy="3.141592653589793 -0.40239793279263236 0.0"/>
         <geometry>
            <mesh filename="package://orcahand_description/assets/urdf/right/visual/right_visual_thumb_dp_skin_mesh.stl"/>
         </geometry>
         <material name="white"/>
      </visual>
      <collision name="right_collision_thumb_dp_skin_mesh">
         <origin xyz="0.002785448336058668 -6.944475247259374e-06 0.016557497442018437" rpy="3.141592653589793 -0.3963953079219906 0.0"/>
         <geometry>
            <mesh filename="package://orcahand_description/assets/urdf/right/collision/right_collision_thumb_dp_skin_mesh.stl"/>
         </geometry>
         <material name="white"/>
      </collision>
   </link>
   <link name="right_thumb_dip_jointbody">
      <inertial>
         <origin xyz="0.0 0.0 0.0" rpy="0.0 0.0 0.0"/>
         <mass value="0.001"/>
         <inertia ixx="1e-09" iyy="1e-09" izz="1e-09" ixy="0" ixz="0" iyz="0"/>
      </inertial>
   </link>
   <joint type="revolute" name="right_thumb_dip">
      <parent link="right_thumb_ip"/>
      <child link="right_thumb_dip_jointbody"/>
      <origin xyz="0.0005 0.0 0.033" rpy="0.0 0.0 0.0"/>
      <axis xyz="0.0 -1.0 0.0"/>
      <limit lower="-0.85384" upper="1.45" effort="100" velocity="100"/>
   </joint>
   <joint type="fixed" name="right_thumb_dip_offset">
      <parent link="right_thumb_dip_jointbody"/>
      <child link="right_thumb_dp"/>
      <origin xyz="-0.0 -0.0 -0.0" rpy="0.0 0.0 0.0"/>
   </joint>
   <link name="right_thumb_fingertip">
      <inertial>
         <origin xyz="-0.003 0.0 0.025" rpy="0.0 0.0 0.0"/>
         <mass value="0.0"/>
         <inertia ixx="0.0" iyy="0.0" izz="0.0" ixy="0" ixz="0" iyz="0"/>
      </inertial>
   </link>
   <joint type="fixed" name="thumb_dp2right_thumb_fingertip_fixed_offset">
      <parent link="right_thumb_dp"/>
      <child link="right_thumb_fingertip"/>
      <origin xyz="0.003 0.0 0.025" rpy="0.0 0.0 0.0"/>
   </joint>
   <link name="right_index_mp">
      <inertial>
         <origin xyz="0.01155 0.0 -4e-05" rpy="-2.6535897932333796e-06 -1.5707926535897931 3.141592653589793"/>
         <mass value="0.00498"/>
         <inertia ixx="3.4e-07" iyy="3.1e-07" izz="2e-07" ixy="0" ixz="0" iyz="0"/>
      </inertial>
      <visual name="right_visual_index_mp_mesh">
         <origin xyz="0.010698479000335614 -1.389065483476104e-05 -0.00027878809319396305" rpy="3.1297715721932393 -1.5066740246432395 2.4424906541753444e-15"/>
         <geometry>
            <mesh filename="package://orcahand_description/assets/urdf/right/visual/right_visual_index_mp_mesh.stl"/>
         </geometry>
         <material name="white"/>
      </visual>
      <collision name="right_collision_index_mp_mesh">
         <origin xyz="0.01047824184159959 -4.456734197189478e-05 -0.00016480462181888062" rpy="0.928212641576985 -1.5147947849129795 2.212627507721145"/>
         <geometry>
            <mesh filename="package://orcahand_description/assets/urdf/right/collision/right_collision_index_mp_mesh.stl"/>
         </geometry>
         <material name="white"/>
      </collision>
   </link>
   <link name="right_index_abd_jointbody">
      <inertial>
         <origin xyz="0.0 0.0 0.0" rpy="0.0 0.0 0.0"/>
         <mass value="0.001"/>
         <inertia ixx="1e-09" iyy="1e-09" izz="1e-09" ixy="0" ixz="0" iyz="0"/>
      </inertial>
   </link>
   <joint type="revolute" name="right_index_abd">
      <parent link="right_palm"/>
      <child link="right_index_abd_jointbody"/>
      <origin xyz="-0.024088797002689358 0.0018999642829399502 0.025164928786148736" rpy="1.6066999999999996 1.13552 -0.05339000000000049"/>
      <axis xyz="0.0 0.0 -1.0"/>
      <limit lower="-1.04577" upper="0.24577" effort="100" velocity="100"/>
   </joint>
   <joint type="fixed" name="right_index_abd_offset">
      <parent link="right_index_abd_jointbody"/>
      <child link="right_index_mp"/>
      <origin xyz="-0.02 -0.0 -0.0" rpy="0.0 0.0 0.0"/>
   </joint>
   <link name="right_index_pp">
      <inertial>
         <origin xyz="0.00135 2e-05 0.01637" rpy="0.00034 0.020550000000000068 0.00038"/>
         <mass value="0.0165"/>
         <inertia ixx="2.39e-06" iyy="2.31e-06" izz="7.1e-07" ixy="0" ixz="0" iyz="0"/>
      </inertial>
      <visual name="right_visual_index_pp_mesh">
         <origin xyz="0.0012791981098529209 4.322204569499314e-05 0.016098661080179" rpy="0.005516325755706635 0.035101984887858206 0.03910570256058449"/>
         <geometry>
            <mesh filename="package://orcahand_description/assets/urdf/right/visual/right_visual_index_pp_mesh.stl"/>
         </geometry>
         <material name="white"/>
      </visual>
      <collision name="right_collision_index_pp_mesh">
         <origin xyz="0.0013516740131344841 1.1247422892215125e-05 0.015681803525061735" rpy="0.0 0.042883356216690816 0.0"/>
         <geometry>
            <mesh filename="package://orcahand_description/assets/urdf/right/collision/right_collision_index_pp_mesh.stl"/>
         </geometry>
         <material name="white"/>
      </collision>
      <visual name="right_visual_index_pp_skin_mesh">
         <origin xyz="0.0016617007377281573 7.13567847691717e-08 0.018763861638214734" rpy="3.141592653589793 -0.8345404465359767 0.0"/>
         <geometry>
            <mesh filename="package://orcahand_description/assets/urdf/right/visual/right_visual_index_pp_skin_mesh.stl"/>
         </geometry>
         <material name="white"/>
      </visual>
      <collision name="right_collision_index_pp_skin_mesh">
         <origin xyz="0.0016773866527582534 -5.5310131701629075e-06 0.018740870134460883" rpy="3.141592653589793 -0.8259683678608123 0.0"/>
         <geometry>
            <mesh filename="package://orcahand_description/assets/urdf/right/collision/right_collision_index_pp_skin_mesh.stl"/>
         </geometry>
         <material name="white"/>
      </collision>
   </link>
   <link name="right_index_mcp_jointbody">
      <inertial>
         <origin xyz="0.0 0.0 0.0" rpy="0.0 0.0 0.0"/>
         <mass value="0.001"/>
         <inertia ixx="1e-09" iyy="1e-09" izz="1e-09" ixy="0" ixz="0" iyz="0"/>
      </inertial>
   </link>
   <joint type="revolute" name="right_index_mcp">
      <parent link="right_index_mp"/>
      <child link="right_index_mcp_jointbody"/>
      <origin xyz="0.0 0.0 0.0" rpy="3.141592653589793 -1.5707926535897931 3.141592653589793"/>
      <axis xyz="0.0 -1.0 0.0"/>
      <limit lower="-0.34907" upper="1.65806" effort="100" velocity="100"/>
   </joint>
   <joint type="fixed" name="right_index_mcp_offset">
      <parent link="right_index_mcp_jointbody"/>
      <child link="right_index_pp"/>
      <origin xyz="-0.0 -0.0 -0.0" rpy="0.0 0.0 0.0"/>
   </joint>
   <link name="right_index_ip">
      <inertial>
         <origin xyz="0.00071 1e-05 0.01929" rpy="-0.00042000000000000023 -0.18548999999999993 0.004400000000000001"/>
         <mass value="0.01521"/>
         <inertia ixx="2.08e-06" iyy="2.06e-06" izz="5.4e-07" ixy="0" ixz="0" iyz="0"/>
      </inertial>
      <visual name="right_visual_index_ip_mesh">
         <origin xyz="0.0010416798025929732 7.836534536637715e-05 0.011793743862640304" rpy="-0.03448776902850714 -0.0034390239986910043 1.5709149778710771"/>
         <geometry>
            <mesh filename="package://orcahand_description/assets/urdf/right/visual/right_visual_index_ip_mesh.stl"/>
         </geometry>
         <material name="white"/>
      </visual>
      <collision name="right_collision_index_ip_mesh">
         <origin xyz="0.001264526142413497 -1.637119615337525e-05 0.01147202326458154" rpy="0.0018005943049513862 0.0 1.5707963267948966"/>
         <geometry>
            <mesh filename="package://orcahand_description/assets/urdf/right/collision/right_collision_index_ip_mesh.stl"/>
         </geometry>
         <material name="white"/>
      </collision>
      <visual name="right_visual_index_ip_skin_mesh">
         <origin xyz="0.0006177579160319044 -2.8394632435300543e-07 0.02298191534250252" rpy="0.0 -0.4563594541722644 0.0"/>
         <geometry>
            <mesh filename="package://orcahand_description/assets/urdf/right/visual/right_visual_index_ip_skin_mesh.stl"/>
         </geometry>
         <material name="white"/>
      </visual>
      <collision name="right_collision_index_ip_skin_mesh">
         <origin xyz="0.0006216739383467692 2.432607491983251e-06 0.02302104994067657" rpy="0.0 -0.4457042297154219 0.0"/>
         <geometry>
            <mesh filename="package://orcahand_description/assets/urdf/right/collision/right_collision_index_ip_skin_mesh.stl"/>
         </geometry>
         <material name="white"/>
      </collision>
   </link>
   <link name="right_index_pip_jointbody">
      <inertial>
         <origin xyz="0.0 0.0 0.0" rpy="0.0 0.0 0.0"/>
         <mass value="0.001"/>
         <inertia ixx="1e-09" iyy="1e-09" izz="1e-09" ixy="0" ixz="0" iyz="0"/>
      </inertial>
   </link>
   <joint type="revolute" name="right_index_pip">
      <parent link="right_index_pp"/>
      <child link="right_index_pip_jointbody"/>
      <origin xyz="0.0005 0.0 0.038" rpy="0.0 0.0 0.0"/>
      <axis xyz="0.0 -1.0 0.0"/>
      <limit lower="-0.34907" upper="1.88496" effort="100" velocity="100"/>
   </joint>
   <joint type="fixed" name="right_index_pip_offset">
      <parent link="right_index_pip_jointbody"/>
      <child link="right_index_ip"/>
      <origin xyz="-0.0 -0.0 -0.0" rpy="0.0 0.0 0.0"/>
   </joint>
   <link name="right_index_fingertip">
      <inertial>
         <origin xyz="-0.009 0.0 0.035" rpy="0.0 0.0 0.0"/>
         <mass value="0.0"/>
         <inertia ixx="0.0" iyy="0.0" izz="0.0" ixy="0" ixz="0" iyz="0"/>
      </inertial>
   </link>
   <joint type="fixed" name="right_index_ip2right_index_fingertip_fixed_offset">
      <parent link="right_index_ip"/>
      <child link="right_index_fingertip"/>
      <origin xyz="-0.009 0.0 0.035" rpy="0.0 0.0 0.0"/>
   </joint>
   <link name="right_middle_mp">
      <inertial>
         <origin xyz="0.01155 0.0 -4e-05" rpy="-2.6535897932333796e-06 -1.5707926535897931 3.141592653589793"/>
         <mass value="0.00498"/>
         <inertia ixx="3.4e-07" iyy="3.1e-07" izz="2e-07" ixy="0" ixz="0" iyz="0"/>
      </inertial>
      <visual name="right_visual_middle_mp_mesh">
         <origin xyz="0.010698479000335614 -1.389065483476104e-05 -0.00027878809319396305" rpy="3.1297715721932393 -1.5066740246432395 2.4424906541753444e-15"/>
         <geometry>
            <mesh filename="package://orcahand_description/assets/urdf/right/visual/right_visual_middle_mp_mesh.stl"/>
         </geometry>
         <material name="white"/>
      </visual>
      <collision name="right_collision_middle_mp_mesh">
         <origin xyz="0.01047824184159959 -4.456734197189478e-05 -0.00016480462181888062" rpy="0.928212641576985 -1.5147947849129795 2.212627507721145"/>
         <geometry>
            <mesh filename="package://orcahand_description/assets/urdf/right/collision/right_collision_middle_mp_mesh.stl"/>
         </geometry>
         <material name="white"/>
      </collision>
   </link>
   <link name="right_middle_abd_jointbody">
      <inertial>
         <origin xyz="0.0 0.0 0.0" rpy="0.0 0.0 0.0"/>
         <mass value="0.001"/>
         <inertia ixx="1e-09" iyy="1e-09" izz="1e-09" ixy="0" ixz="0" iyz="0"/>
      </inertial>
   </link>
   <joint type="revolute" name="right_middle_abd">
      <parent link="right_palm"/>
      <child link="right_middle_abd_jointbody"/>
      <origin xyz="-7.346410206776621e-08 0.0 0.030000000000134926" rpy="-1.5707926536208807 1.5707926535897934 3.141592653558706"/>
      <axis xyz="0.0 0.0 -1.0"/>
      <limit lower="-0.64577" upper="0.64577" effort="100" velocity="100"/>
   </joint>
   <joint type="fixed" name="right_middle_abd_offset">
      <parent link="right_middle_abd_jointbody"/>
      <child link="right_middle_mp"/>
      <origin xyz="-0.02 -0.0 -0.0" rpy="0.0 0.0 0.0"/>
   </joint>
   <link name="right_middle_pp">
      <inertial>
         <origin xyz="0.00144 2e-05  0.02021" rpy="-2.9999999999999916e-05 -0.013859999999999983 -0.0005999999999999998"/>
         <mass value="0.02006"/>
         <inertia ixx="3.78e-06" iyy="3.69e-06" izz="8.9e-07" ixy="0" ixz="0" iyz="0"/>
      </inertial>
      <visual name="right_visual_middle_pp_mesh">
         <origin xyz="0.001283421930192045 3.6963342684240676e-05 0.02022720775953102" rpy="0.004564296284170381 0.027656376334468602 0.037580505677349094"/>
         <geometry>
            <mesh filename="package://orcahand_description/assets/urdf/right/visual/right_visual_middle_pp_mesh.stl"/>
         </geometry>
         <material name="white"/>
      </visual>
      <collision name="right_collision_middle_pp_mesh">
         <origin xyz="0.001339380770656077 -6.845101857801683e-06 0.02011933923689832" rpy="-0.0006410664486678006 0.029880005436222712 -5.421010862427522e-20"/>
         <geometry>
            <mesh filename="package://orcahand_description/assets/urdf/right/collision/right_collision_middle_pp_mesh.stl"/>
         </geometry>
         <material name="white"/>
      </collision>
      <visual name="right_visual_middle_pp_skin_mesh">
         <origin xyz="0.001729699116189442 2.0144468929163878e-08 0.022938288977938984" rpy="0.0 -0.22312530126972074 0.0"/>
         <geometry>
            <mesh filename="package://orcahand_description/assets/urdf/right/visual/right_visual_middle_pp_skin_mesh.stl"/>
         </geometry>
         <material name="white"/>
      </visual>
      <collision name="right_collision_middle_pp_skin_mesh">
         <origin xyz="0.0017525848624676125 2.7252940732883304e-06 0.022885135333659" rpy="0.0 -0.22006061767397878 0.0"/>
         <geometry>
            <mesh filename="package://orcahand_description/assets/urdf/right/collision/right_collision_middle_pp_skin_mesh.stl"/>
         </geometry>
         <material name="white"/>
      </collision>
   </link>
   <link name="right_middle_mcp_jointbody">
      <inertial>
         <origin xyz="0.0 0.0 0.0" rpy="0.0 0.0 0.0"/>
         <mass value="0.001"/>
         <inertia ixx="1e-09" iyy="1e-09" izz="1e-09" ixy="0" ixz="0" iyz="0"/>
      </inertial>
   </link>
   <joint type="revolute" name="right_middle_mcp">
      <parent link="right_middle_mp"/>
      <child link="right_middle_mcp_jointbody"/>
      <origin xyz="0.0 0.0 0.0" rpy="3.141592653589793 -1.5707926535897931 3.141592653589793"/>
      <axis xyz="0.0 -1.0 0.0"/>
      <limit lower="-0.34907" upper="1.58825" effort="100" velocity="100"/>
   </joint>
   <joint type="fixed" name="right_middle_mcp_offset">
      <parent link="right_middle_mcp_jointbody"/>
      <child link="right_middle_pp"/>
      <origin xyz="-0.0 -0.0 -0.0" rpy="0.0 0.0 0.0"/>
   </joint>
   <link name="right_middle_ip">
      <inertial>
         <origin xyz="-0.00071 1e-05 0.01929" rpy="-0.00042000000000000023 -0.18548999999999993 0.004400000000000001"/>
         <mass value="0.01521"/>
         <inertia ixx="2.08e-06" iyy="2.06e-06" izz="5.4e-07" ixy="0" ixz="0" iyz="0"/>
      </inertial>
      <visual name="right_visual_middle_ip_mesh">
         <origin xyz="-0.0010416798025929732 7.836534536637715e-05 0.011793743862640304" rpy="-0.03448776902850714 -0.0034390239986910043 1.5709149778710771"/>
         <geometry>
            <mesh filename="package://orcahand_description/assets/urdf/right/visual/right_visual_middle_ip_mesh.stl"/>
         </geometry>
         <material name="white"/>
      </visual>
      <collision name="right_collision_middle_ip_mesh">
         <origin xyz="-0.0012645261424134968 -1.637119615337525e-05 0.01147202326458154" rpy="-0.0018005943049513862 0.0 1.5707963267948966"/>
         <geometry>
            <mesh filename="package://orcahand_description/assets/urdf/right/collision/right_collision_middle_ip_mesh.stl"/>
         </geometry>
         <material name="white"/>
      </collision>
      <visual name="right_visual_middle_ip_skin_mesh">
         <origin xyz="-0.0006177579160319044 -2.8394632435300543e-07 0.02298191534250252" rpy="0.0 -0.4563594541722644 0.0"/>
         <geometry>
            <mesh filename="package://orcahand_description/assets/urdf/right/visual/right_visual_middle_ip_skin_mesh.stl"/>
         </geometry>
         <material name="white"/>
      </visual>
      <collision name="right_collision_middle_ip_skin_mesh">
         <origin xyz="-0.0006216739383467692 2.432607491983251e-06 0.02302104994067657" rpy="0.0 -0.4457042297154219 0.0"/>
         <geometry>
            <mesh filename="package://orcahand_description/assets/urdf/right/collision/right_collision_middle_ip_skin_mesh.stl"/>
         </geometry>
         <material name="white"/>
      </collision>
   </link>
   <link name="right_middle_pip_jointbody">
      <inertial>
         <origin xyz="0.0 0.0 0.0" rpy="0.0 0.0 0.0"/>
         <mass value="0.001"/>
         <inertia ixx="1e-09" iyy="1e-09" izz="1e-09" ixy="0" ixz="0" iyz="0"/>
      </inertial>
   </link>
   <joint type="revolute" name="right_middle_pip">
      <parent link="right_middle_pp"/>
      <child link="right_middle_pip_jointbody"/>
      <origin xyz="0.0 0.0 0.0" rpy="-2.6535897934554242e-06 1.5707926535897934 3.141592653589793"/>
      <axis xyz="0.0 1.0 0.0"/>
      <limit lower="-0.34907" upper="1.8675" effort="100" velocity="100"/>
   </joint>
   <joint type="fixed" name="right_middle_pip_offset">
      <parent link="right_middle_pip_jointbody"/>
      <child link="right_middle_ip"/>
      <origin xyz="-0.0 -0.0 -0.0" rpy="0.0 0.0 0.0"/>
   </joint>
      <link name="right_middle_fingertip">
      <inertial>
         <origin xyz="-0.009 0.0 0.035" rpy="0.0 0.0 0.0"/>
         <mass value="0.0"/>
         <inertia ixx="0.0" iyy="0.0" izz="0.0" ixy="0" ixz="0" iyz="0"/>
      </inertial>
   </link>
   <joint type="fixed" name="right_middle_ip2right_index_fingertip_fixed_offset">
      <parent link="right_middle_ip"/>
      <child link="right_middle_fingertip"/>
      <origin xyz="-0.009 0.0 0.035" rpy="0.0 0.0 0.0"/>
   </joint>
   <link name="right_ring_mp">
      <inertial>
         <origin xyz="-0.01155 0.0 -4e-05" rpy="-2.6535897932333796e-06 1.5707926535897931 3.141592653589793"/>
         <mass value="0.00498"/>
         <inertia ixx="3.4e-07" iyy="3.1e-07" izz="2e-07" ixy="0" ixz="0" iyz="0"/>
      </inertial>
      <visual name="right_visual_ring_mp_mesh">
         <origin xyz="-0.010698479000335614 -1.389065483476104e-05 -0.00027878809319396294" rpy="3.1297715721932393 -1.5066740246432395 2.4424906541753444e-15"/>
         <geometry>
            <mesh filename="package://orcahand_description/assets/urdf/right/visual/right_visual_ring_mp_mesh.stl"/>
         </geometry>
         <material name="white"/>
      </visual>
      <collision name="right_collision_ring_mp_mesh">
         <origin xyz="-0.01047824184159959 -4.456734197189478e-05 -0.00016480462181888051" rpy="0.928212641576985 -1.5147947849129795 2.212627507721145"/>
         <geometry>
            <mesh filename="package://orcahand_description/assets/urdf/right/collision/right_collision_ring_mp_mesh.stl"/>
         </geometry>
         <material name="white"/>
      </collision>
   </link>
   <link name="right_ring_abd_jointbody">
      <inertial>
         <origin xyz="0.0 0.0 0.0" rpy="0.0 0.0 0.0"/>
         <mass value="0.001"/>
         <inertia ixx="1e-09" iyy="1e-09" izz="1e-09" ixy="0" ixz="0" iyz="0"/>
      </inertial>
   </link>
   <joint type="revolute" name="right_ring_abd">
      <parent link="right_palm"/>
      <child link="right_ring_abd_jointbody"/>
      <origin xyz="0.021521022061295733 0.0015382095479525787 0.020824784431525818" rpy="-1.5359699999999998 1.30836 -3.05441"/>
      <axis xyz="0.0 0.0 -1.0"/>
      <limit lower="-0.47577" upper="0.80577" effort="100" velocity="100"/>
   </joint>
   <joint type="fixed" name="right_ring_abd_offset">
      <parent link="right_ring_abd_jointbody"/>
      <child link="right_ring_mp"/>
      <origin xyz="-0.02 -0.0 -0.0" rpy="0.0 0.0 0.0"/>
   </joint>
   <link name="right_ring_pp">
      <inertial>
         <origin xyz="0.00144 2e-05 0.02021" rpy="-2.9999999999999916e-05 0.013859999999999983 0.0005999999999999998"/>
         <mass value="0.02006"/>
         <inertia ixx="3.78e-06" iyy="3.69e-06" izz="8.9e-07" ixy="0" ixz="0" iyz="0"/>
      </inertial>
      <visual name="right_visual_ring_pp_mesh">
         <origin xyz="0.001283421930192045 3.6963342684240676e-05 0.02022720775953102" rpy="0.004564296284170381 0.027656376334468602 0.037580505677349094"/>
         <geometry>
            <mesh filename="package://orcahand_description/assets/urdf/right/visual/right_visual_ring_pp_mesh.stl"/>
         </geometry>
         <material name="white"/>
      </visual>
      <collision name="right_collision_ring_pp_mesh">
         <origin xyz="0.001339380770656077 -6.845101857801683e-06 0.02011933923689832" rpy="-0.0006410664486678006 0.029880005436222712 -5.421010862427522e-20"/>
         <geometry>
            <mesh filename="package://orcahand_description/assets/urdf/right/collision/right_collision_ring_pp_mesh.stl"/>
         </geometry>
         <material name="white"/>
      </collision>
      <visual name="right_visual_ring_pp_skin_mesh">
         <origin xyz="0.001729699116189442 2.0144468929163878e-08 0.022938288977938984" rpy="0.0 -0.22312530126972074 0.0"/>
         <geometry>
            <mesh filename="package://orcahand_description/assets/urdf/right/visual/right_visual_ring_pp_skin_mesh.stl"/>
         </geometry>
         <material name="white"/>
      </visual>
      <collision name="right_collision_ring_pp_skin_mesh">
         <origin xyz="0.0017525848624676125 2.7252940732883304e-06 0.022885135333659" rpy="0.0 -0.22006061767397878 0.0"/>
         <geometry>
            <mesh filename="package://orcahand_description/assets/urdf/right/collision/right_collision_ring_pp_skin_mesh.stl"/>
         </geometry>
         <material name="white"/>
      </collision>
   </link>
   <link name="right_ring_mcp_jointbody">
      <inertial>
         <origin xyz="0.0 0.0 0.0" rpy="0.0 0.0 0.0"/>
         <mass value="0.001"/>
         <inertia ixx="1e-09" iyy="1e-09" izz="1e-09" ixy="0" ixz="0" iyz="0"/>
      </inertial>
   </link>
   <joint type="revolute" name="right_ring_mcp">
      <parent link="right_ring_mp"/>
      <child link="right_ring_mcp_jointbody"/>
      <origin xyz="0.0 0.0 0.0" rpy="3.141592653589793 -1.5707926535897931 3.141592653589793"/>
      <axis xyz="0.0 -1.0 0.0"/>
      <limit lower="-0.34907" upper="1.58825" effort="100" velocity="100"/>
   </joint>
   <joint type="fixed" name="right_ring_mcp_offset">
      <parent link="right_ring_mcp_jointbody"/>
      <child link="right_ring_pp"/>
      <origin xyz="-0.0 -0.0 -0.0" rpy="0.0 0.0 0.0"/>
   </joint>
   <link name="right_ring_ip">
      <inertial>
         <origin xyz="-0.00071 1e-05 0.01929" rpy="-0.00042000000000000023 -0.18548999999999993 0.004400000000000001"/>
         <mass value="0.01521"/>
         <inertia ixx="2.08e-06" iyy="2.06e-06" izz="5.4e-07" ixy="0" ixz="0" iyz="0"/>
      </inertial>
      <visual name="right_visual_ring_ip_mesh">
         <origin xyz="-0.001041679802592973 7.836534536637725e-05 0.011793743862640297" rpy="-0.03448776902850714 -0.0034390239986910043 1.5706776757187162"/>
         <geometry>
            <mesh filename="package://orcahand_description/assets/urdf/right/visual/right_visual_ring_ip_mesh.stl"/>
         </geometry>
         <material name="white"/>
      </visual>
      <collision name="right_collision_ring_ip_mesh">
         <origin xyz="-0.0012645261424134968 -1.6371196153375355e-05 0.011472023264581544" rpy="-0.0018005943049513862 0.0 1.5707963267948966"/>
         <geometry>
            <mesh filename="package://orcahand_description/assets/urdf/right/collision/right_collision_ring_ip_mesh.stl"/>
         </geometry>
         <material name="white"/>
      </collision>
      <visual name="right_visual_ring_ip_skin_mesh">
         <origin xyz="-0.0006177579160319049 -2.8394632435326436e-07 0.02298191534250252" rpy="0.0 -0.45635945417226464 0.0"/>
         <geometry>
            <mesh filename="package://orcahand_description/assets/urdf/right/visual/right_visual_ring_ip_skin_mesh.stl"/>
         </geometry>
         <material name="white"/>
      </visual>
      <collision name="right_collision_ring_ip_skin_mesh">
         <origin xyz="-0.0006216739383467691 2.4326074919833366e-06 0.023021049940676577" rpy="0.0 -0.4457042297154219 0.0"/>
         <geometry>
            <mesh filename="package://orcahand_description/assets/urdf/right/collision/right_collision_ring_ip_skin_mesh.stl"/>
         </geometry>
         <material name="white"/>
      </collision>
   </link>
   <link name="right_ring_pip_jointbody">
      <inertial>
         <origin xyz="0.0 0.0 0.0" rpy="0.0 0.0 0.0"/>
         <mass value="0.001"/>
         <inertia ixx="1e-09" iyy="1e-09" izz="1e-09" ixy="0" ixz="0" iyz="0"/>
      </inertial>
   </link>
   <joint type="revolute" name="right_ring_pip">
      <parent link="right_ring_pp"/>
      <child link="right_ring_pip_jointbody"/>
      <origin xyz="0.0005 0.0 0.046" rpy="0.0 0.0 0.0"/>
      <axis xyz="0.0 -1.0 0.0"/>
      <limit lower="-0.34907" upper="1.8675" effort="100" velocity="100"/>
   </joint>
   <joint type="fixed" name="right_ring_pip_offset">
      <parent link="right_ring_pip_jointbody"/>
      <child link="right_ring_ip"/>
      <origin xyz="-0.0 -0.0 -0.0" rpy="0.0 0.0 0.0"/>
   </joint>
      <link name="right_ring_fingertip">
      <inertial>
         <origin xyz="-0.009 0.0 0.035" rpy="0.0 0.0 0.0"/>
         <mass value="0.0"/>
         <inertia ixx="0.0" iyy="0.0" izz="0.0" ixy="0" ixz="0" iyz="0"/>
      </inertial>
   </link>
   <joint type="fixed" name="right_ring_ip2right_index_fingertip_fixed_offset">
      <parent link="right_ring_ip"/>
      <child link="right_ring_fingertip"/>
      <origin xyz="-0.009 0.0 0.035" rpy="0.0 0.0 0.0"/>
   </joint>
  
  <!-- ========================================= -->
  <!-- LEFT ORCA HAND EXTENDED - INLINE (NO WORLD/BASE) -->
  <!-- Copied from orcahand_left_extended.urdf -->
  <!-- ========================================= -->
  
  <!-- LEFT HAND: Copy ALL links from orcahand_left_extended.urdf starting with left_tower -->
  <!-- (Exact copy from the provided file, all visual/collision/inertial properties) -->
  
  <!-- Connection from connector to hand -->
  <joint name="left_connector_to_tower" type="fixed">
    <parent link="left_connector_link"/>
    <child link="left_tower"/>
    <origin xyz="0 0 0.02" rpy="0 0 0"/>
  </joint>

  <!-- ALL LEFT HAND LINKS AND JOINTS FROM orcahand_left_extended.urdf -->
  <!-- (The entire content from left_tower onwards, all fingers, etc.) -->

  <!-- ========================================= -->
  <!-- RIGHT ORCA HAND EXTENDED - INLINE (NO WORLD/BASE) -->
  <!-- Copied from orcahand_right_extended.urdf -->
  <!-- ========================================= -->
  
  <!-- RIGHT HAND: Copy ALL links from orcahand_right_extended.urdf starting with right_tower -->
  
  <!-- Connection from connector to hand -->
  <joint name="right_connector_to_tower" type="fixed">
    <parent link="right_connector_link"/>
    <child link="right_tower"/>
    <origin xyz="0 0 0.02" rpy="0 0 0"/>
  </joint>

  <!-- ALL RIGHT HAND LINKS AND JOINTS FROM orcahand_right_extended.urdf -->
  <!-- (The entire content from right_tower onwards, all fingers, etc.) -->

</robot>
   <joint type="revolute" name="right_ring_abd">
      <parent link="right_palm"/>
      <child link="right_ring_abd_jointbody"/>
      <origin xyz="0.021521022061295733 0.0015382095479525787 0.020824784431525818" rpy="-1.5359699999999998 1.30836 -3.05441"/>
      <axis xyz="0.0 0.0 -1.0"/>
      <limit lower="-0.47577" upper="0.80577" effort="100" velocity="100"/>
   </joint>
   <joint type="fixed" name="right_ring_abd_offset">
      <parent link="right_ring_abd_jointbody"/>
      <child link="right_ring_mp"/>
      <origin xyz="-0.02 -0.0 -0.0" rpy="0.0 0.0 0.0"/>
   </joint>
   <link name="right_ring_pp">
      <inertial>
         <origin xyz="0.00144 2e-05 0.02021" rpy="-2.9999999999999916e-05 0.013859999999999983 0.0005999999999999998"/>
         <mass value="0.02006"/>
         <inertia ixx="3.78e-06" iyy="3.69e-06" izz="8.9e-07" ixy="0" ixz="0" iyz="0"/>
      </inertial>
      <visual name="right_visual_ring_pp_mesh">
         <origin xyz="0.001283421930192045 3.6963342684240676e-05 0.02022720775953102" rpy="0.004564296284170381 0.027656376334468602 0.037580505677349094"/>
         <geometry>
            <mesh filename="package://orcahand_description/assets/urdf/right/visual/right_visual_ring_pp_mesh.stl"/>
         </geometry>
         <material name="white"/>
      </visual>
      <collision name="right_collision_ring_pp_mesh">
         <origin xyz="0.001339380770656077 -6.845101857801683e-06 0.02011933923689832" rpy="-0.0006410664486678006 0.029880005436222712 -5.421010862427522e-20"/>
         <geometry>
            <mesh filename="package://orcahand_description/assets/urdf/right/collision/right_collision_ring_pp_mesh.stl"/>
         </geometry>
         <material name="white"/>
      </collision>
      <visual name="right_visual_ring_pp_skin_mesh">
         <origin xyz="0.001729699116189442 2.0144468929163878e-08 0.022938288977938984" rpy="0.0 -0.22312530126972074 0.0"/>
         <geometry>
            <mesh filename="package://orcahand_description/assets/urdf/right/visual/right_visual_ring_pp_skin_mesh.stl"/>
         </geometry>
         <material name="white"/>
      </visual>
      <collision name="right_collision_ring_pp_skin_mesh">
         <origin xyz="0.0017525848624676125 2.7252940732883304e-06 0.022885135333659" rpy="0.0 -0.22006061767397878 0.0"/>
         <geometry>
            <mesh filename="package://orcahand_description/assets/urdf/right/collision/right_collision_ring_pp_skin_mesh.stl"/>
         </geometry>
         <material name="white"/>
      </collision>
   </link>
   <link name="right_ring_mcp_jointbody">
      <inertial>
         <origin xyz="0.0 0.0 0.0" rpy="0.0 0.0 0.0"/>
         <mass value="0.001"/>
         <inertia ixx="1e-09" iyy="1e-09" izz="1e-09" ixy="0" ixz="0" iyz="0"/>
      </inertial>
   </link>
   <joint type="revolute" name="right_ring_mcp">
      <parent link="right_ring_mp"/>
      <child link="right_ring_mcp_jointbody"/>
      <origin xyz="0.0 0.0 0.0" rpy="3.141592653589793 -1.5707926535897931 3.141592653589793"/>
      <axis xyz="0.0 -1.0 0.0"/>
      <limit lower="-0.34907" upper="1.58825" effort="100" velocity="100"/>
   </joint>
   <joint type="fixed" name="right_ring_mcp_offset">
      <parent link="right_ring_mcp_jointbody"/>
      <child link="right_ring_pp"/>
      <origin xyz="-0.0 -0.0 -0.0" rpy="0.0 0.0 0.0"/>
   </joint>
   <link name="right_ring_ip">
      <inertial>
         <origin xyz="0.00071 1e-05 0.01929" rpy="-0.00042000000000000023 -0.18548999999999993 0.004400000000000001"/>
         <mass value="0.01521"/>
         <inertia ixx="2.08e-06" iyy="2.06e-06" izz="5.4e-07" ixy="0" ixz="0" iyz="0"/>
      </inertial>
      <visual name="right_visual_ring_ip_mesh">
         <origin xyz="0.0010416798025929732 7.836534536637715e-05 0.011793743862640304" rpy="-0.03448776902850714 -0.0034390239986910043 1.5709149778710771"/>
         <geometry>
            <mesh filename="package://orcahand_description/assets/urdf/right/visual/right_visual_ring_ip_mesh.stl"/>
         </geometry>
         <material name="white"/>
      </visual>
      <collision name="right_collision_ring_ip_mesh">
         <origin xyz="0.001264526142413497 -1.637119615337525e-05 0.01147202326458154" rpy="0.0018005943049513862 0.0 1.5707963267948966"/>
         <geometry>
            <mesh filename="package://orcahand_description/assets/urdf/right/collision/right_collision_ring_ip_mesh.stl"/>
         </geometry>
         <material name="white"/>
      </collision>
      <visual name="right_visual_ring_ip_skin_mesh">
         <origin xyz="0.0006177579160319044 -2.8394632435300543e-07 0.02298191534250252" rpy="0.0 -0.4563594541722644 0.0"/>
         <geometry>
            <mesh filename="package://orcahand_description/assets/urdf/right/visual/right_visual_ring_ip_skin_mesh.stl"/>
         </geometry>
         <material name="white"/>
      </visual>
      <collision name="right_collision_ring_ip_skin_mesh">
         <origin xyz="0.0006216739383467692 2.432607491983251e-06 0.02302104994067657" rpy="0.0 -0.4457042297154219 0.0"/>
         <geometry>
            <mesh filename="package://orcahand_description/assets/urdf/right/collision/right_collision_ring_ip_skin_mesh.stl"/>
         </geometry>
         <material name="white"/>
      </collision>
   </link>
   <link name="right_ring_pip_jointbody">
      <inertial>
         <origin xyz="0.0 0.0 0.0" rpy="0.0 0.0 0.0"/>
         <mass value="0.001"/>
         <inertia ixx="1e-09" iyy="1e-09" izz="1e-09" ixy="0" ixz="0" iyz="0"/>
      </inertial>
   </link>
   <joint type="revolute" name="right_ring_pip">
      <parent link="right_ring_pp"/>
      <child link="right_ring_pip_jointbody"/>
      <origin xyz="0.0005 0.0 0.046" rpy="0.0 0.0 0.0"/>
      <axis xyz="0.0 -1.0 0.0"/>
      <limit lower="-0.34907" upper="1.8675" effort="100" velocity="100"/>
   </joint>
   <joint type="fixed" name="right_ring_pip_offset">
      <parent link="right_ring_pip_jointbody"/>
      <child link="right_ring_ip"/>
      <origin xyz="-0.0 -0.0 -0.0" rpy="0.0 0.0 0.0"/>
   </joint>
      <link name="right_ring_fingertip">
      <inertial>
         <origin xyz="-0.009 0.0 0.035" rpy="0.0 0.0 0.0"/>
         <mass value="0.0"/>
         <inertia ixx="0.0" iyy="0.0" izz="0.0" ixy="0" ixz="0" iyz="0"/>
      </inertial>
   </link>
   <joint type="fixed" name="right_ring_ip2right_index_fingertip_fixed_offset">
      <parent link="right_ring_ip"/>
      <child link="right_ring_fingertip"/>
      <origin xyz="-0.009 0.0 0.035" rpy="0.0 0.0 0.0"/>
   </joint>
   <link name="right_pinky_mp">
      <inertial>
         <origin xyz="0.01155 0.0 -4e-05" rpy="-2.6535897932333796e-06 -1.5707926535897931 3.141592653589793"/>
         <mass value="0.00498"/>
         <inertia ixx="3.4e-07" iyy="3.1e-07" izz="2e-07" ixy="0" ixz="0" iyz="0"/>
      </inertial>
      <visual name="right_visual_pinky_mp_mesh">
         <origin xyz="0.010698479000335614 -1.389065483476104e-05 -0.00027878809319396305" rpy="3.1297715721932393 -1.5066740246432395 2.4424906541753444e-15"/>
         <geometry>
            <mesh filename="package://orcahand_description/assets/urdf/right/visual/right_visual_pinky_mp_mesh.stl"/>
         </geometry>
         <material name="white"/>
      </visual>
      <collision name="right_collision_pinky_mp_mesh">
         <origin xyz="0.01047824184159959 -4.456734197189478e-05 -0.00016480462181888062" rpy="0.928212641576985 -1.5147947849129795 2.212627507721145"/>
         <geometry>
            <mesh filename="package://orcahand_description/assets/urdf/right/collision/right_collision_pinky_mp_mesh.stl"/>
         </geometry>
         <material name="white"/>
      </collision>
   </link>
   <link name="right_pinky_abd_jointbody">
      <inertial>
         <origin xyz="0.0 0.0 0.0" rpy="0.0 0.0 0.0"/>
         <mass value="0.001"/>
         <inertia ixx="1e-09" iyy="1e-09" izz="1e-09" ixy="0" ixz="0" iyz="0"/>
      </inertial>
   </link>
   <joint type="revolute" name="right_pinky_abd">
      <parent link="right_palm"/>
      <child link="right_pinky_abd_jointbody"/>
      <origin xyz="0.04258452932438962 0.004988143142003794 0.007243722937596895" rpy="-1.49694 0.8614899999999999 -2.8837299999999995"/>
      <axis xyz="0.0 0.0 -1.0"/>
      <limit lower="-0.12244" upper="1.1691" effort="100" velocity="100"/>
   </joint>
   <joint type="fixed" name="right_pinky_abd_offset">
      <parent link="right_pinky_abd_jointbody"/>
      <child link="right_pinky_mp"/>
      <origin xyz="-0.02 -0.0 -0.0" rpy="0.0 0.0 0.0"/>
   </joint>
   <link name="right_pinky_pp">
      <inertial>
         <origin xyz="0.00135 2e-05 0.01383" rpy="0.0003700000000000001 0.03263000000000016 0.00034"/>
         <mass value="0.01402"/>
         <inertia ixx="1.7e-06" iyy="1.64e-06" izz="5.9e-07" ixy="0" ixz="0" iyz="0"/>
      </inertial>
      <visual name="right_visual_pinky_pp_mesh">
         <origin xyz="0.0012998948492342203 7.159773213648307e-06 0.013619877706625217" rpy="0.0 0.04338716477372251 0.0"/>
         <geometry>
            <mesh filename="package://orcahand_description/assets/urdf/right/visual/right_visual_pinky_pp_mesh.stl"/>
         </geometry>
         <material name="white"/>
      </visual>
      <collision name="right_collision_pinky_pp_mesh">
         <origin xyz="0.0013560375396256981 0.00012710825491742077 0.013446327660739959" rpy="0.00708255798627546 0.04763590113115046 0.0"/>
         <geometry>
            <mesh filename="package://orcahand_description/assets/urdf/right/collision/right_collision_pinky_pp_mesh.stl"/>
         </geometry>
         <material name="white"/>
      </collision>
      <visual name="right_visual_pinky_pp_skin_mesh">
         <origin xyz="0.0015424443589898442 1.6522252825510055e-07 0.016259641785170875" rpy="3.141592653589793 -1.2480960827956862 0.0"/>
         <geometry>
            <mesh filename="package://orcahand_description/assets/urdf/right/visual/right_visual_pinky_pp_skin_mesh.stl"/>
         </geometry>
         <material name="white"/>
      </visual>
      <collision name="right_collision_pinky_pp_skin_mesh">
         <origin xyz="0.0015528244655451595 6.48072440430664e-06 0.016246657621879965" rpy="3.141592653589793 -1.243771833702049 0.0"/>
         <geometry>
            <mesh filename="package://orcahand_description/assets/urdf/right/collision/right_collision_pinky_pp_skin_mesh.stl"/>
         </geometry>
         <material name="white"/>
      </collision>
   </link>
   <link name="right_pinky_mcp_jointbody">
      <inertial>
         <origin xyz="0.0 0.0 0.0" rpy="0.0 0.0 0.0"/>
         <mass value="0.001"/>
         <inertia ixx="1e-09" iyy="1e-09" izz="1e-09" ixy="0" ixz="0" iyz="0"/>
      </inertial>
   </link>
   <joint type="revolute" name="right_pinky_mcp">
      <parent link="right_pinky_mp"/>
      <child link="right_pinky_mcp_jointbody"/>
      <origin xyz="0.0 0.0 0.0" rpy="3.141592653589793 -1.5707926535897931 3.141592653589793"/>
      <axis xyz="0.0 -1.0 0.0"/>
      <limit lower="-0.34907" upper="1.71042" effort="100" velocity="100"/>
   </joint>
   <joint type="fixed" name="right_pinky_mcp_offset">
      <parent link="right_pinky_mcp_jointbody"/>
      <child link="right_pinky_pp"/>
      <origin xyz="-0.0 -0.0 -0.0" rpy="0.0 0.0 0.0"/>
   </joint>
   <link name="right_pinky_ip">
      <inertial>
         <origin xyz="0.00071 1e-05 0.01929" rpy="-0.00042000000000000023 -0.18548999999999993 0.004400000000000001"/>
         <mass value="0.01521"/>
         <inertia ixx="2.08e-06" iyy="2.06e-06" izz="5.4e-07" ixy="0" ixz="0" iyz="0"/>
      </inertial>
      <visual name="right_visual_pinky_ip_mesh">
         <origin xyz="0.0010416798025929732 7.836534536637715e-05 0.011793743862640304" rpy="-0.03448776902850714 -0.0034390239986910043 1.5709149778710771"/>
         <geometry>
            <mesh filename="package://orcahand_description/assets/urdf/right/visual/right_visual_pinky_ip_mesh.stl"/>
         </geometry>
         <material name="white"/>
      </visual>
      <collision name="right_collision_pinky_ip_mesh">
         <origin xyz="0.001264526142413497 -1.637119615337525e-05 0.01147202326458154" rpy="0.0018005943049513862 0.0 1.5707963267948966"/>
         <geometry>
            <mesh filename="package://orcahand_description/assets/urdf/right/collision/right_collision_pinky_ip_mesh.stl"/>
         </geometry>
         <material name="white"/>
      </collision>
      <visual name="right_visual_pinky_ip_skin_mesh">
         <origin xyz="0.0006177579160319044 -2.8394632435300543e-07 0.02298191534250252" rpy="0.0 -0.4563594541722644 0.0"/>
         <geometry>
            <mesh filename="package://orcahand_description/assets/urdf/right/visual/right_visual_pinky_ip_skin_mesh.stl"/>
         </geometry>
         <material name="white"/>
      </visual>
      <collision name="right_collision_pinky_ip_skin_mesh">
         <origin xyz="0.0006216739383467692 2.432607491983251e-06 0.02302104994067657" rpy="0.0 -0.4457042297154219 0.0"/>
         <geometry>
            <mesh filename="package://orcahand_description/assets/urdf/right/collision/right_collision_pinky_ip_skin_mesh.stl"/>
         </geometry>
         <material name="white"/>
      </collision>
   </link>
   <link name="right_pinky_pip_jointbody">
      <inertial>
         <origin xyz="0.0 0.0 0.0" rpy="0.0 0.0 0.0"/>
         <mass value="0.001"/>
         <inertia ixx="1e-09" iyy="1e-09" izz="1e-09" ixy="0" ixz="0" iyz="0"/>
      </inertial>
   </link>
   <joint type="revolute" name="right_pinky_pip">
      <parent link="right_pinky_pp"/>
      <child link="right_pinky_pip_jointbody"/>
      <origin xyz="0.0005 0.0 0.033" rpy="0.0 0.0 0.0"/>
      <axis xyz="0.0 -1.0 0.0"/>
      <limit lower="-0.34907" upper="1.88496" effort="100" velocity="100"/>
   </joint>
   <joint type="fixed" name="right_pinky_pip_offset">
      <parent link="right_pinky_pip_jointbody"/>
      <child link="right_pinky_ip"/>
      <origin xyz="-0.0 -0.0 -0.0" rpy="0.0 0.0 0.0"/>
   </joint>
   <link name="right_pinky_fingertip">
      <inertial>
         <origin xyz="-0.009 0.0 0.035" rpy="0.0 0.0 0.0"/>
         <mass value="0.0"/>
         <inertia ixx="0.0" iyy="0.0" izz="0.0" ixy="0" ixz="0" iyz="0"/>
      </inertial>
   </link>
   <joint type="fixed" name="right_pinky_ip2right_index_fingertip_fixed_offset">
      <parent link="right_pinky_ip"/>
      <child link="right_pinky_fingertip"/>
      <origin xyz="-0.009 0.0 0.035" rpy="0.0 0.0 0.0"/>
   </joint>
  
  <joint name="right_connector_to_hand" type="fixed">
    <parent link="right_connector_link"/>
    <child link="right_tower"/>
    <origin xyz="0 0 0.02" rpy="0 0 0"/>
  </joint>

  <!-- COPY EXACT CONTENT FROM orcahand_right_extended.urdf FILE PROVIDED ABOVE -->
  <!-- All links and joints starting from right_tower -->

</robot>
  <!-- Copied from orcahand_right_extended.urdf -->
  <!-- NO world or base links! -->
  <!-- ========================================= -->
  
  <joint name="right_connector_to_hand" type="fixed">
    <parent link="right_connector_link"/>
    <child link="right_tower"/>
    <origin xyz="0 0 0.02" rpy="0 0 0"/>
  </joint>

  <!-- Copy ALL links and joints from orcahand_right_extended.urdf starting here -->
  <!-- ...existing code from orcahand_right_extended.urdf... -->

</robot>
  </link>

  <joint name="left_link7_to_connector" type="fixed">
    <parent link="openarm_left_link7"/>
    <child link="left_connector_link"/>
    <origin xyz="0 0 0" rpy="0 0 0"/>
  </joint>

  <!-- ========================================= -->
  <!-- RIGHT CONNECTOR -->
  <!-- ========================================= -->
  
  <link name="right_connector_link">
    <visual>
      <origin xyz="0 0 0" rpy="0 0 0"/>
      <geometry>
        <mesh filename="package://connectors_description/meshes/connector.dae"/>
      </geometry>
    </visual>
    <collision>
      <origin xyz="0 0 0" rpy="0 0 0"/>
      <geometry>
        <mesh filename="package://connectors_description/meshes/connector.stl"/>
      </geometry>
    </collision>
    <inertial>
      <origin xyz="0 0 0" rpy="0 0 0"/>
      <mass value="0.1"/>
      <inertia ixx="0.0001" ixy="0" ixz="0" iyy="0.0001" iyz="0" izz="0.0001"/>
    </inertial>
  </link>

  <joint name="right_link7_to_connector" type="fixed">
    <parent link="openarm_right_link7"/>
    <child link="right_connector_link"/>
    <origin xyz="0 0 0" rpy="0 0 0"/>
  </joint>

  <!-- ========================================= -->
  <!-- LEFT ORCA HAND EXTENDED - INLINE (NO WORLD/BASE) -->
  <!-- Copied from orcahand_left_extended.urdf -->
  <!-- ========================================= -->
  
  <!-- LEFT HAND: Copy ALL links from orcahand_left_extended.urdf starting with left_tower -->
  <!-- (Exact copy from the provided file, all visual/collision/inertial properties) -->
  
  <!-- Connection from connector to hand -->
  <joint name="left_connector_to_tower" type="fixed">
    <parent link="left_connector_link"/>
    <child link="left_tower"/>
    <origin xyz="0 0 0.02" rpy="0 0 0"/>
  </joint>

  <!-- ALL LEFT HAND LINKS AND JOINTS FROM orcahand_left_extended.urdf -->
  <!-- (The entire content from left_tower onwards, all fingers, etc.) -->

  <!-- ========================================= -->
  <!-- RIGHT ORCA HAND EXTENDED - INLINE (NO WORLD/BASE) -->
  <!-- Copied from orcahand_right_extended.urdf -->
  <!-- ========================================= -->
  
  <!-- RIGHT HAND: Copy ALL links from orcahand_right_extended.urdf starting with right_tower -->
  
  <!-- Connection from connector to hand -->
  <joint name="right_connector_to_tower" type="fixed">
    <parent link="right_connector_link"/>
    <child link="right_tower"/>
    <origin xyz="0 0 0.02" rpy="0 0 0"/>
  </joint>

  <!-- ALL RIGHT HAND LINKS AND JOINTS FROM orcahand_right_extended.urdf -->
  <!-- (The entire content from right_tower onwards, all fingers, etc.) -->

</robot>
</robot>
